Workbook

Sheet Pivot
A1: Outcome | B1: Count | C1: Description
A2: AC | B2: 15 | C2: Already Contacted
A3: A | B3: 112 | C3: Answering Machine
A4: DROP | B4: 318 | C4: Dropped
A5: IABDN | B5: 67 | C5: Inbound Abandon
A6: NA | B6: 4418 | C6: No Answer Autodial
A7: AA | B7: 4739 | C7: Answering Machine Autodial
A8: CU | B8: 550 | C8: Client Hung Up
A9: DNC | B9: 44 | C9: Do Not Call
A10: NI | B10: 510 | C10: Not Interested
A11: N | B11: 72 | C11: No Answer
A12: CB | B12: 61 | C12: Busy Tone
A13: AFTHRS | B13: 13 | C13: Inbound After Hours Drop
... A39: None | B39: 110 | C39: New

Sheet Campaign Analysis
A1: Clientele Bellringer Leads Campaign Analysis
B5: Unsuccessful Contacts | C5: Lead Count | D5: Was customer interested in deal? | E5: Lead Count | F5: Successful Contacts | G5: Lead Count | H5: True Contacts | I5: Lead Count
C6: Answering Machine Autodial | D6: =IFERROR(VLOOKUP("Answering Machine Autodial",Pivot!$C$2:$B$39,2,FALSE),0) -> 0 | E6: Sale Made - Completed Mandate | F6: =IFERROR(VLOOKUP("Sale Made - Completed Mandate",Pivot!$C$2:$B$39,2,FALSE),0) -> 0 | G6: Already Contacted | H6: =IFERROR(VLOOKUP("Already Contacted",Pivot!$C$2:$B$39,2,FALSE),0) -> 0 | I6: Client Hung Up | J6: =IFERROR(VLOOKUP("Client Hung Up",Pivot!$C$2:$B$39,2,FALSE),0) -> 0
C7: No Answer Autodial | D7: =IFERROR(VLOOKUP("No Answer Autodial",Pivot!$C$2:$B$39,2,FALSE),0) -> 0 | E7: Sale Made - Pending Mandate | F7: =IFERROR(VLOOKUP("Sale Made - Pending Mandate",Pivot!$C$2:$B$39,2,FALSE),0) -> 0 | G7: Existing Client | H7: =IFERROR(VLOOKUP("Existing Client",Pivot!$C$2:$B$39,2,FALSE),0) -> 0 | I7: CallBack | J7: =IFERROR(VLOOKUP("CallBack",Pivot!$C$2:$B$39,2,FALSE),0) -> 0
C8: Auto Engaged | D8: =IFERROR(VLOOKUP("Auto Engaged",Pivot!$C$2:$B$39,2,FALSE),0) -> 0 | E8: Sale Made | F8: =IFERROR(VLOOKUP("Sale Made",Pivot!$C$2:$B$39,2,FALSE),0) -> 0 | G8: Unemployed | H8: =IFERROR(VLOOKUP("Unemployed",Pivot!$C$2:$B$39,2,FALSE),0) -> 0 | I8: Not Interested | J8: =IFERROR(VLOOKUP("Not Interested",Pivot!$C$2:$B$39,2,FALSE),0) -> 0
C9: Disconnected Number Auto | D9: =IFERROR(VLOOKUP("Disconnected Number Auto",Pivot!$C$2:$B$39,2,FALSE),0) -> 0 | E9: Tyme Bank Account Sale | F9: =IFERROR(VLOOKUP("Tyme Bank Account Sale",Pivot!$C$2:$B$39,2,FALSE),0) -> 0 | G9: Wrong Number | H9: =IFERROR(VLOOKUP("Wrong Number",Pivot!$C$2:$B$39,2,FALSE),0) -> 0 | I9: Not Interested Upfront | J9: =IFERROR(VLOOKUP("Not Interested Upfront",Pivot!$C$2:$B$39,2,FALSE),0) -> 0
C10: Answering Machine | D10: =IFERROR(VLOOKUP("Answering Machine",Pivot!$C$2:$B$39,2,FALSE),0) -> 0 | E10: QA Rework | F10: =IFERROR(VLOOKUP("QA Rework",Pivot!$C$2:$B$39,2,FALSE),0) -> 0 | G10: Do Not Call | H10: =IFERROR(VLOOKUP("Do Not Call",Pivot!$C$2:$B$39,2,FALSE),0) -> 0 | I10: Cannot Afford Premium | J10: =IFERROR(VLOOKUP("Cannot Afford Premium",Pivot!$C$2:$B$39,2,FALSE),0) -> 0
C11: Selected | D11: =IFERROR(VLOOKUP("Selected",Pivot!$C$2:$B$39,2,FALSE),0) -> 0 | E11: If not, Why not? | G11: No Smartphones | H11: =IFERROR(VLOOKUP("No Smartphones",Pivot!$C$2:$B$39,2,FALSE),0) -> 0 | I11: Not interested - Pitched | J11: =IFERROR(VLOOKUP("Not interested - Pitched",Pivot!$C$2:$B$39,2,FALSE),0) -> 0
B12: =D33+F11 -> 0 | C12: No Answer | D12: =IFERROR(VLOOKUP("No Answer",Pivot!$C$2:$B$39,2,FALSE),0) -> 0 | F12: =SUM(F8:F9) -> 0 | G12: Client Deceased | H12: =IFERROR(VLOOKUP("Client Deceased",Pivot!$C$2:$B$39,2,FALSE),0) -> 0 | I12: Affordability | J12: =IFERROR(VLOOKUP("Affordability",Pivot!$C$2:$B$39,2,FALSE),0) -> 0
C13: Busy Tone | D13: =IFERROR(VLOOKUP("Busy Tone",Pivot!$C$2:$B$39,2,FALSE),0) -> 0 | G13: Right Party Not Available | H13: =IFERROR(VLOOKUP("Right Party Not Available",Pivot!$C$2:$B$39,2,FALSE),0) -> 0 | I13: Quoted Client Not Interested | J13: =IFERROR(VLOOKUP("Quoted Client Not Interested",Pivot!$C$2:$B$39,2,FALSE),0) -> 0
C14: Dropped | D14: =IFERROR(VLOOKUP("Dropped",Pivot!$C$2:$B$39,2,FALSE),0) -> 0 | G14: Client Overage Limit | H14: =IFERROR(VLOOKUP("Client Overage Limit",Pivot!$C$2:$B$39,2,FALSE),0) -> 0 | I14: Not interested business does not use speed point mac | J14: =IFERROR(VLOOKUP("Not interested business does not use speed point mac",Pivot!$C$2:$B$39,2,FALSE),0) -> 0
C15: New | D15: =IFERROR(VLOOKUP("New",Pivot!$C$2:$B$39,2,FALSE),0) -> 0 | G15: Language Barrier | H15: =IFERROR(VLOOKUP("Language Barrier",Pivot!$C$2:$B$39,2,FALSE),0) -> 0 | I15: Call Back Technical Error | J15: =IFERROR(VLOOKUP("Call Back Technical Error",Pivot!$C$2:$B$39,2,FALSE),0) -> 0
C16: Call Dropped | D16: =IFERROR(VLOOKUP("Call Dropped",Pivot!$C$2:$B$39,2,FALSE),0) -> 0 | G16: Non SA Citizen | H16: =IFERROR(VLOOKUP("Non SA Citizen",Pivot!$C$2:$B$39,2,FALSE),0) -> 0 | I16: Not Interested Transaction Fees | J16: =IFERROR(VLOOKUP("Not Interested Transaction Fees",Pivot!$C$2:$B$39,2,FALSE),0) -> 0
C17: Inbound After Hours Drop | D17: =IFERROR(VLOOKUP("Inbound After Hours Drop",Pivot!$C$2:$B$39,2,FALSE),0) -> 0 | F17: =H33+J22 -> 0 | G17: No Bank Account | H17: =IFERROR(VLOOKUP("No Bank Account",Pivot!$C$2:$B$39,2,FALSE),0) -> 0 | I17: Cannot Afford | J17: =IFERROR(VLOOKUP("Cannot Afford",Pivot!$C$2:$B$39,2,FALSE),0) -> 0
C18: TPS Registered Number | D18: =IFERROR(VLOOKUP("TPS Registered Number",Pivot!$C$2:$B$39,2,FALSE),0) -> 0 | G18: Client Underage | H18: =IFERROR(VLOOKUP("Client Underage",Pivot!$C$2:$B$39,2,FALSE),0) -> 0 | I18: Not Interested Household Contents | J18: =IFERROR(VLOOKUP("Not Interested Household Contents",Pivot!$C$2:$B$39,2,FALSE),0) -> 0
C19: Temporary Disconnected Number | D19: =IFERROR(VLOOKUP("Temporary Disconnected Number",Pivot!$C$2:$B$39,2,FALSE),0) -> 0 | G19: Go To The Branch | H19: =IFERROR(VLOOKUP("Go To The Branch",Pivot!$C$2:$B$39,2,FALSE),0) -> 0 | I19: Call Back Hold | J19: =IFERROR(VLOOKUP("Call Back Hold",Pivot!$C$2:$B$39,2,FALSE),0) -> 0
C20: Bad Line Quality | D20: =IFERROR(VLOOKUP("Bad Line Quality",Pivot!$C$2:$B$39,2,FALSE),0) -> 0 | G20: Completed | H20: =IFERROR(VLOOKUP("Completed",Pivot!$C$2:$B$39,2,FALSE),0) -> 0 | I20: Declined Sale | J20: =IFERROR(VLOOKUP("Declined Sale",Pivot!$C$2:$B$39,2,FALSE),0) -> 0
C21: Inbound Abandon | D21: =IFERROR(VLOOKUP("Inbound Abandon",Pivot!$C$2:$B$39,2,FALSE),0) -> 0 | G21: Cannot Afford Upfront Payment | H21: =IFERROR(VLOOKUP("Cannot Afford Upfront Payment",Pivot!$C$2:$B$39,2,FALSE),0) -> 0
C22: Outbound Pre-Routing Drop | D22: =IFERROR(VLOOKUP("Outbound Pre-Routing Drop",Pivot!$C$2:$B$39,2,FALSE),0) -> 0 | G22: Account Suspended | H22: =IFERROR(VLOOKUP("Account Suspended",Pivot!$C$2:$B$39,2,FALSE),0) -> 0 | J22: =SUBTOTAL(109,J6:J20) -> 0
C23: Engaged | D23: =IFERROR(VLOOKUP("Engaged",Pivot!$C$2:$B$39,2,FALSE),0) -> 0 | G23: Insured at another company | H23: =IFERROR(VLOOKUP("Insured at another company",Pivot!$C$2:$B$39,2,FALSE),0) -> 0
C24: Disconnected | D24: =IFERROR(VLOOKUP("Disconnected",Pivot!$C$2:$B$39,2,FALSE),0) -> 0 | G24: Scheduled Appointment | H24: =IFERROR(VLOOKUP("Scheduled Appointment",Pivot!$C$2:$B$39,2,FALSE),0) -> 0
C25: CONGESTED | D25: =IFERROR(VLOOKUP("CONGESTED",Pivot!$C$2:$B$39,2,FALSE),0) -> 0 | G25: Refund Request | H25: =IFERROR(VLOOKUP("Refund Request",Pivot!$C$2:$B$39,2,FALSE),0) -> 0
C26: Flow Inbound Abandon | D26: =IFERROR(VLOOKUP("Flow Inbound Abandon",Pivot!$C$2:$B$39,2,FALSE),0) -> 0 | G26: Does Not Qualify | H26: =IFERROR(VLOOKUP("Does Not Qualify",Pivot!$C$2:$B$39,2,FALSE),0) -> 0
C27: Multiple Calls | D27: =IFERROR(VLOOKUP("Multiple Calls",Pivot!$C$2:$B$39,2,FALSE),0) -> 0 | G27: Does Not Have a Business | H27: =IFERROR(VLOOKUP("Does Not Have a Business",Pivot!$C$2:$B$39,2,FALSE),0) -> 0
C28: Missed | D28: =IFERROR(VLOOKUP("Missed",Pivot!$C$2:$B$39,2,FALSE),0) -> 0 | G28: Refer To Store - Doesn't want to complete online | H28: =IFERROR(VLOOKUP("Refer To Store - Doesn't want to complete online",Pivot!$C$2:$B$39,2,FALSE),0) -> 0
C29: Answered | D29: =IFERROR(VLOOKUP("Answered",Pivot!$C$2:$B$39,2,FALSE),0) -> 0 | G29: Does Not Need It Now | H29: =IFERROR(VLOOKUP("Does Not Need It Now",Pivot!$C$2:$B$39,2,FALSE),0) -> 0
C30: Customer drop | D30: =IFERROR(VLOOKUP("Customer drop",Pivot!$C$2:$B$39,2,FALSE),0) -> 0 | G30: Technical Issue | H30: =IFERROR(VLOOKUP("Technical Issue",Pivot!$C$2:$B$39,2,FALSE),0) -> 0
C31: Auto Dial Disconnected | D31: =IFERROR(VLOOKUP("Auto Dial Disconnected",Pivot!$C$2:$B$39,2,FALSE),0) -> 0 | G31: Unsuccessful Application | H31: =IFERROR(VLOOKUP("Unsuccessful Application",Pivot!$C$2:$B$39,2,FALSE),0) -> 0
C32: Disconnected Number Temporary | D32: =IFERROR(VLOOKUP("Disconnected Number Temporary",Pivot!$C$2:$B$39,2,FALSE),0) -> 0
H33: =SUM(H6:H31) -> 0
D34: =SUM(D6:D32) -> 0
C38: =F12+H33+J22 -> 0
C39: =J22+F12 -> 0
A40: STATS | C40: =SUM(F8:F9) -> 0
A41: Successful Contacts | B41: =F12 -> 0 | C41: =C40/C39 -> 0
A42: True Contacts (TC) | B42: =J22 -> 0 | C42: =F12/B12 -> 0
A43: Conversions | B43: =F8 -> 0 | C43: =B12 -> 0
A44: Conversion ratio based on TC | B44: =C42/C41 -> 0
A45: Contact ratio | B45: =(C40+C41)/B12 -> 0
A46: TOTAL LEADS | B46: =B12 -> 0
...
