Workbook

Sheet Processed Data
A1: Contact Id | B1: Customer Id | C1: Lead Reference | D1: List Id | E1: List Name | F1: Title | G1: Firstname | H1: Lastname | I1: Gender | J1: Last Outcome | K1: Outcome Description | L1: Called Count | M1: Last Called Date | N1: Last User | O1: Created At | P1: Updated At | Q1: Address1 | R1: Address2 | S1: Address3 | T1: Town | U1: County | V1: Country | W1: Postcode | X1: Email Address | Y1: Tel1 | Z1: Tel2 | AA1: Tel3 | AB1: Tel4 | AC1: Tel5 | AD1: Tel6 | AE1: Owner Username | AF1: Security Phrase | AG1: Source Reference | AH1: Industry | AI1: Company Name | AJ1: Website | AK1: Customer Reference | AL1: Dob
A2: ID_1 | J2: 13861083;0c5d0900-c88d-437b-a16f-855d45126772;;111111118;Vodacom Life 20260324;;;;;DROP;5;2026-05-22 | K2: 13861083;0c5d0900-c88d-437b-a16f-855d45126772;;111111118;Vodacom Life 20260324;;;;;DROP;5;2026-05-22 09:16:46+02;system;2026-03-24 09:54:08+02;2026-03-24 09:54:08+02;;;;;;;;;27605282905;;;;;;;;prepaid life;;;;;
A3: ID_2 | J3: 13861084;c5d4ca87-d640-4db8-b8be-7c1dd38b63af;;111111118;Vodacom Life 20260324;;;27606185640;;IABDN; | K3: 13861084;c5d4ca87-d640-4db8-b8be-7c1dd38b63af;;111111118;Vodacom Life 20260324;;;27606185640;;IABDN;5;2026-05-22 11:51:27+02;system;2026-03-24 09:54:08+02;2026-03-24 09:54:08+02;;;;;;;;;27606185640;;;;;;;;prepaid life;;;;;
A4: ID_3 | J4: 13861234;489008fa-ad7f-49ff-9a68-451c4e7ec13b;;111111118;Vodacom Life 20260324;;;;;CBACK;1;2026-03-2 | K4: 13861234;489008fa-ad7f-49ff-9a68-451c4e7ec13b;;111111118;Vodacom Life 20260324;;;;;CBACK;1;2026-03-24 10:38:27+02;Maureen Ntsoko;2026-03-24 09:54:08+02;2026-03-24 09:54:08+02;;;;;;;;;27823683861;;;;;;;;prepaid life;;;;;
A5: ID_4 | J5: 13861136;48c9b311-7abb-4cc1-8240-dde69d266a34;;111111118;Vodacom Life 20260324;;;;;ADC;5;2026-05-22 | K5: 13861136;48c9b311-7abb-4cc1-8240-dde69d266a34;;111111118;Vodacom Life 20260324;;;;;ADC;5;2026-05-22 08:59:37+02;system;2026-03-24 09:54:08+02;2026-03-24 09:54:08+02;;;;;;;;;27720108006;;;;;;;;prepaid life;;;;;
A6: ID_5 | J6: 13861085;dc6cfabe-9de8-4779-adff-cb53994b319c;;111111118;Vodacom Life 20260324;;;;;AA;5;2026-05-22 0 | K6: 13861085;dc6cfabe-9de8-4779-adff-cb53994b319c;;111111118;Vodacom Life 20260324;;;;;AA;5;2026-05-22 08:49:31+02;system;2026-03-24 09:54:08+02;2026-03-24 09:54:08+02;;;;;;;;;27606480924;;;;;;;;prepaid life;;;;;
A7: ID_6 | J7: 13861137;094011ee-2667-4e61-9de6-3642cde0b618;;111111118;Vodacom Life 20260324;;;;;AA;5;2026-05-22 0 | K7: 13861137;094011ee-2667-4e61-9de6-3642cde0b618;;111111118;Vodacom Life 20260324;;;;;AA;5;2026-05-22 08:59:37+02;system;2026-03-24 09:54:08+02;2026-03-24 09:54:08+02;;;;;;;;;27720706970;;;;;;;;prepaid life;;;;;
A8: ID_7 | J8: 13861235;640ee428-2c69-4b84-bf0d-8d5e24dd28f2;;111111118;Vodacom Life 20260324;;;;;A;5;2026-05-22 09 | K8: 13861235;640ee428-2c69-4b84-bf0d-8d5e24dd28f2;;111111118;Vodacom Life 20260324;;;;;A;5;2026-05-22 09:17:50+02;Maureen Ntsoko;2026-03-24 09:54:08+02;2026-03-24 09:54:08+02;;;;;;;;;27823837477;;;;;;;;prepaid life;;;;;
A9: ID_8 | J9: 13861086;179aad27-f968-47ae-9bff-cc888a423731;;111111118;Vodacom Life 20260324;;;;;NA;5;2026-05-22 0 | K9: 13861086;179aad27-f968-47ae-9bff-cc888a423731;;111111118;Vodacom Life 20260324;;;;;NA;5;2026-05-22 08:49:31+02;system;2026-03-24 09:54:08+02;2026-03-24 09:54:08+02;;;;;;;;;27606717498;;;;;;;;prepaid life;;;;;
A10: ID_9 | J10: 13861236;5a3407d8-0ac8-4b82-aa2f-eb7ef1def6bb;;111111118;Vodacom Life 20260324;;;27824211928;;CU;5;2 | K10: 13861236;5a3407d8-0ac8-4b82-aa2f-eb7ef1def6bb;;111111118;Vodacom Life 20260324;;;27824211928;;CU;5;2026-05-22 09:18:32+02;Maureen Ntsoko;2026-03-24 09:54:08+02;2026-03-24 09:54:08+02;;;;;;;;;27824211928;;;;;;;;prepaid life;;;;;
A11: ID_10 | J11: 13861138;9c4f6d52-8657-4df5-a17e-59b232094a56;;111111118;Vodacom Life 20260324;;;;;NI;2;2026-04-08 1 | K11: 13861138;9c4f6d52-8657-4df5-a17e-59b232094a56;;111111118;Vodacom Life 20260324;;;;;NI;2;2026-04-08 12:31:01+02;Thandile Nokubeni;2026-03-24 09:54:08+02;2026-03-24 09:54:08+02;;;;;;;;;27721187654;;;;;;;;prepaid life;;;;;
A12: ID_11 | J12: 13861087;ad9d8772-1e11-4ffa-be5c-034082e5ef79;;111111118;Vodacom Life 20260324;;;;;AA;5;2026-05-22 0 | K12: 13861087;ad9d8772-1e11-4ffa-be5c-034082e5ef79;;111111118;Vodacom Life 20260324;;;;;AA;5;2026-05-22 08:49:39+02;system;2026-03-24 09:54:08+02;2026-03-24 09:54:08+02;;;;;;;;;27606748902;;;;;;;;prepaid life;;;;;
A13: ID_12 | J13: 13861139;981de2ce-a439-4ce3-90d1-0028b16bd23c;;111111118;Vodacom Life 20260324;;;;;AA;5;2026-05-22 0 | K13: 13861139;981de2ce-a439-4ce3-90d1-0028b16bd23c;;111111118;Vodacom Life 20260324;;;;;AA;5;2026-05-22 08:59:37+02;system;2026-03-24 09:54:08+02;2026-03-24 09:54:08+02;;;;;;;;;27721534526;;;;;;;;prepaid life;;;;;
... A4842: ID_4841 | J4842: 13865556;a6b04108-f01f-4105-9681-6af68e1b8665;;111111118;Vodacom Life 20260324;;;;;AA;5;2026-05-22 0 | K4842: 13865556;a6b04108-f01f-4105-9681-6af68e1b8665;;111111118;Vodacom Life 20260324;;;;;AA;5;2026-05-22 09:21:35+02;system;2026-03-24 09:54:08+02;2026-03-24 09:54:08+02;;;;;;;;;27818957465;;;;;;;;prepaid life;;;;;

Sheet Pivot
A1: Outcome Description | B1: Count
A2: 13861083;0c5d0900-c88d-437b-a16f-855d45126772;;111111118;Vodacom Life 20260324;;;;;DROP;5;2026-05-22 | B2: 1
A3: 13861084;c5d4ca87-d640-4db8-b8be-7c1dd38b63af;;111111118;Vodacom Life 20260324;;;27606185640;;IABDN; | B3: 1
A4: 13861085;dc6cfabe-9de8-4779-adff-cb53994b319c;;111111118;Vodacom Life 20260324;;;;;AA;5;2026-05-22 0 | B4: 1
A5: 13861086;179aad27-f968-47ae-9bff-cc888a423731;;111111118;Vodacom Life 20260324;;;;;NA;5;2026-05-22 0 | B5: 1
A6: 13861087;ad9d8772-1e11-4ffa-be5c-034082e5ef79;;111111118;Vodacom Life 20260324;;;;;AA;5;2026-05-22 0 | B6: 1
A7: 13861088;c47227ba-ff07-49ea-845b-7b577e29d9ff;;111111118;Vodacom Life 20260324;;;;;AE;5;2026-05-22 0 | B7: 1
A8: 13861089;368802fd-67d3-47ed-8021-c09435abaa9f;;111111118;Vodacom Life 20260324;;;;;NIUP;3;2026-04-14 | B8: 1
A9: 13861090;27f1b666-acc4-4779-9a03-93a6b99efea6;;111111118;Vodacom Life 20260324;;;;;AA;5;2026-05-22 0 | B9: 1
A10: 13861091;de4ce3df-6e26-4aa5-9f2c-79ee95ab62f8;;111111118;Vodacom Life 20260324;;;;;AF;2;2026-04-08 1 | B10: 1
A11: 13861092;86279b16-5d2d-4db6-ab7d-5ccf65e7cc41;;111111118;Vodacom Life 20260324;;;;;AA;5;2026-05-22 0 | B11: 1
A12: 13861093;33f5d8e1-3ebf-4a39-8fa2-441000968d0c;;111111118;Vodacom Life 20260324;;;;;AE;5;2026-05-22 0 | B12: 1
A13: 13861094;5f27c699-2c9c-4624-8d29-3c1eca923e8a;;111111118;Vodacom Life 20260324;;;;;CBACK;5;2026-05-2 | B13: 1
... A4843: Grand Total | B4843: 4841

Sheet Campaign Analysis
A1: Clientele Bellringer Leads Campaign Analysis
B5: Unsuccessful Contacts | C5: Lead Count | D5: Interested in Deal? | E5: Lead Count | F5: Successful Contacts | G5: Lead Count | H5: True Contacts | I5: Lead Count
B6: Answering Machine Autodial | C6: =IFERROR(VLOOKUP("Answering Machine Autodial", Pivot!$A$2:$B$4842, 2, FALSE), 0) -> 0 | D6: Sale Made - Completed Mandate | E6: =IFERROR(VLOOKUP("Sale Made - Completed Mandate", Pivot!$A$2:$B$4842, 2, FALSE), 0) -> 0 | F6: Already Contacted | G6: =IFERROR(VLOOKUP("Already Contacted", Pivot!$A$2:$B$4842, 2, FALSE), 0) -> 0 | H6: Client Hung Up | I6: =IFERROR(VLOOKUP("Client Hung Up", Pivot!$A$2:$B$4842, 2, FALSE), 0) -> 0
B7: No Answer Autodial | C7: =IFERROR(VLOOKUP("No Answer Autodial", Pivot!$A$2:$B$4842, 2, FALSE), 0) -> 0 | D7: Sale Made - Pending Mandate | E7: =IFERROR(VLOOKUP("Sale Made - Pending Mandate", Pivot!$A$2:$B$4842, 2, FALSE), 0) -> 0 | F7: Existing Client | G7: =IFERROR(VLOOKUP("Existing Client", Pivot!$A$2:$B$4842, 2, FALSE), 0) -> 0 | H7: CallBack | I7: =IFERROR(VLOOKUP("CallBack", Pivot!$A$2:$B$4842, 2, FALSE), 0) -> 0
B8: Auto Engaged | C8: =IFERROR(VLOOKUP("Auto Engaged", Pivot!$A$2:$B$4842, 2, FALSE), 0) -> 0 | D8: Sale Made | E8: =IFERROR(VLOOKUP("Sale Made", Pivot!$A$2:$B$4842, 2, FALSE), 0) -> 0 | F8: Unemployed | G8: =IFERROR(VLOOKUP("Unemployed", Pivot!$A$2:$B$4842, 2, FALSE), 0) -> 0 | H8: Not Interested | I8: =IFERROR(VLOOKUP("Not Interested", Pivot!$A$2:$B$4842, 2, FALSE), 0) -> 0
B9: Disconnected Number Auto | C9: =IFERROR(VLOOKUP("Disconnected Number Auto", Pivot!$A$2:$B$4842, 2, FALSE), 0) -> 0 | D9: Tyme Bank Account Sale | E9: =IFERROR(VLOOKUP("Tyme Bank Account Sale", Pivot!$A$2:$B$4842, 2, FALSE), 0) -> 0 | F9: Wrong Number | G9: =IFERROR(VLOOKUP("Wrong Number", Pivot!$A$2:$B$4842, 2, FALSE), 0) -> 0 | H9: Not Interested Upfront | I9: =IFERROR(VLOOKUP("Not Interested Upfront", Pivot!$A$2:$B$4842, 2, FALSE), 0) -> 0
B10: Answering Machine | C10: =IFERROR(VLOOKUP("Answering Machine", Pivot!$A$2:$B$4842, 2, FALSE), 0) -> 0 | D10: QA Rework | E10: =IFERROR(VLOOKUP("QA Rework", Pivot!$A$2:$B$4842, 2, FALSE), 0) -> 0 | F10: Do Not Call | G10: =IFERROR(VLOOKUP("Do Not Call", Pivot!$A$2:$B$4842, 2, FALSE), 0) -> 0 | H10: Cannot Afford Premium | I10: =IFERROR(VLOOKUP("Cannot Afford Premium", Pivot!$A$2:$B$4842, 2, FALSE), 0) -> 0
B11: Selected | C11: =IFERROR(VLOOKUP("Selected", Pivot!$A$2:$B$4842, 2, FALSE), 0) -> 0 | F11: No Smartphones | G11: =IFERROR(VLOOKUP("No Smartphones", Pivot!$A$2:$B$4842, 2, FALSE), 0) -> 0 | H11: Not interested - Pitched | I11: =IFERROR(VLOOKUP("Not interested - Pitched", Pivot!$A$2:$B$4842, 2, FALSE), 0) -> 0
B12: No Answer | C12: =IFERROR(VLOOKUP("No Answer", Pivot!$A$2:$B$4842, 2, FALSE), 0) -> 0 | F12: Client Deceased | G12: =IFERROR(VLOOKUP("Client Deceased", Pivot!$A$2:$B$4842, 2, FALSE), 0) -> 0 | H12: Affordability | I12: =IFERROR(VLOOKUP("Affordability", Pivot!$A$2:$B$4842, 2, FALSE), 0) -> 0
B13: Busy Tone | C13: =IFERROR(VLOOKUP("Busy Tone", Pivot!$A$2:$B$4842, 2, FALSE), 0) -> 0 | F13: Right Party Not Available | G13: =IFERROR(VLOOKUP("Right Party Not Available", Pivot!$A$2:$B$4842, 2, FALSE), 0) -> 0 | H13: Quoted Client Not Interested | I13: =IFERROR(VLOOKUP("Quoted Client Not Interested", Pivot!$A$2:$B$4842, 2, FALSE), 0) -> 0
B14: Dropped | C14: =IFERROR(VLOOKUP("Dropped", Pivot!$A$2:$B$4842, 2, FALSE), 0) -> 0 | F14: Client Overage Limit | G14: =IFERROR(VLOOKUP("Client Overage Limit", Pivot!$A$2:$B$4842, 2, FALSE), 0) -> 0 | H14: Not interested business does not use speed point mac | I14: =IFERROR(VLOOKUP("Not interested business does not use speed point mac", Pivot!$A$2:$B$4842, 2, FALSE), 0) -> 0
B15: New | C15: =IFERROR(VLOOKUP("New", Pivot!$A$2:$B$4842, 2, FALSE), 0) -> 0 | F15: Language Barrier | G15: =IFERROR(VLOOKUP("Language Barrier", Pivot!$A$2:$B$4842, 2, FALSE), 0) -> 0 | H15: Call Back Technical Error | I15: =IFERROR(VLOOKUP("Call Back Technical Error", Pivot!$A$2:$B$4842, 2, FALSE), 0) -> 0
B16: Call Dropped | C16: =IFERROR(VLOOKUP("Call Dropped", Pivot!$A$2:$B$4842, 2, FALSE), 0) -> 0 | F16: Non SA Citizen | G16: =IFERROR(VLOOKUP("Non SA Citizen", Pivot!$A$2:$B$4842, 2, FALSE), 0) -> 0 | H16: Not Interested Transaction Fees | I16: =IFERROR(VLOOKUP("Not Interested Transaction Fees", Pivot!$A$2:$B$4842, 2, FALSE), 0) -> 0
B17: Inbound After Hours Drop | C17: =IFERROR(VLOOKUP("Inbound After Hours Drop", Pivot!$A$2:$B$4842, 2, FALSE), 0) -> 0 | F17: No Bank Account | G17: =IFERROR(VLOOKUP("No Bank Account", Pivot!$A$2:$B$4842, 2, FALSE), 0) -> 0 | H17: Cannot Afford | I17: =IFERROR(VLOOKUP("Cannot Afford", Pivot!$A$2:$B$4842, 2, FALSE), 0) -> 0
B18: TPS Registered Number | C18: =IFERROR(VLOOKUP("TPS Registered Number", Pivot!$A$2:$B$4842, 2, FALSE), 0) -> 0 | F18: Client Underage | G18: =IFERROR(VLOOKUP("Client Underage", Pivot!$A$2:$B$4842, 2, FALSE), 0) -> 0 | H18: Not Interested Household Contents | I18: =IFERROR(VLOOKUP("Not Interested Household Contents", Pivot!$A$2:$B$4842, 2, FALSE), 0) -> 0
B19: Temporary Disconnected Number | C19: =IFERROR(VLOOKUP("Temporary Disconnected Number", Pivot!$A$2:$B$4842, 2, FALSE), 0) -> 0 | F19: Go To The Branch | G19: =IFERROR(VLOOKUP("Go To The Branch", Pivot!$A$2:$B$4842, 2, FALSE), 0) -> 0 | H19: Call Back Hold | I19: =IFERROR(VLOOKUP("Call Back Hold", Pivot!$A$2:$B$4842, 2, FALSE), 0) -> 0
B20: Bad Line Quality | C20: =IFERROR(VLOOKUP("Bad Line Quality", Pivot!$A$2:$B$4842, 2, FALSE), 0) -> 0 | F20: Completed | G20: =IFERROR(VLOOKUP("Completed", Pivot!$A$2:$B$4842, 2, FALSE), 0) -> 0 | H20: Declined Sale | I20: =IFERROR(VLOOKUP("Declined Sale", Pivot!$A$2:$B$4842, 2, FALSE), 0) -> 0
B21: Inbound Abandon | C21: =IFERROR(VLOOKUP("Inbound Abandon", Pivot!$A$2:$B$4842, 2, FALSE), 0) -> 0 | F21: Cannot Afford Upfront Payment | G21: =IFERROR(VLOOKUP("Cannot Afford Upfront Payment", Pivot!$A$2:$B$4842, 2, FALSE), 0) -> 0
B22: Outbound Pre-Routing Drop | C22: =IFERROR(VLOOKUP("Outbound Pre-Routing Drop", Pivot!$A$2:$B$4842, 2, FALSE), 0) -> 0 | F22: Account Suspended | G22: =IFERROR(VLOOKUP("Account Suspended", Pivot!$A$2:$B$4842, 2, FALSE), 0) -> 0
B23: Engaged | C23: =IFERROR(VLOOKUP("Engaged", Pivot!$A$2:$B$4842, 2, FALSE), 0) -> 0 | F23: Insured at another company | G23: =IFERROR(VLOOKUP("Insured at another company", Pivot!$A$2:$B$4842, 2, FALSE), 0) -> 0
B24: Disconnected | C24: =IFERROR(VLOOKUP("Disconnected", Pivot!$A$2:$B$4842, 2, FALSE), 0) -> 0 | F24: Scheduled Appointment | G24: =IFERROR(VLOOKUP("Scheduled Appointment", Pivot!$A$2:$B$4842, 2, FALSE), 0) -> 0
B25: CONGESTED | C25: =IFERROR(VLOOKUP("CONGESTED", Pivot!$A$2:$B$4842, 2, FALSE), 0) -> 0 | F25: Refund Request | G25: =IFERROR(VLOOKUP("Refund Request", Pivot!$A$2:$B$4842, 2, FALSE), 0) -> 0
B26: Flow Inbound Abandon | C26: =IFERROR(VLOOKUP("Flow Inbound Abandon", Pivot!$A$2:$B$4842, 2, FALSE), 0) -> 0 | F26: Does Not Qualify | G26: =IFERROR(VLOOKUP("Does Not Qualify", Pivot!$A$2:$B$4842, 2, FALSE), 0) -> 0
B27: Multiple Calls | C27: =IFERROR(VLOOKUP("Multiple Calls", Pivot!$A$2:$B$4842, 2, FALSE), 0) -> 0 | F27: Does Not Have a Business | G27: =IFERROR(VLOOKUP("Does Not Have a Business", Pivot!$A$2:$B$4842, 2, FALSE), 0) -> 0
B28: Missed | C28: =IFERROR(VLOOKUP("Missed", Pivot!$A$2:$B$4842, 2, FALSE), 0) -> 0 | F28: Refer To Store - Doesn't want to complete online | G28: =IFERROR(VLOOKUP("Refer To Store - Doesn't want to complete online", Pivot!$A$2:$B$4842, 2, FALSE), 0) -> 0
B29: Answered | C29: =IFERROR(VLOOKUP("Answered", Pivot!$A$2:$B$4842, 2, FALSE), 0) -> 0 | F29: Does Not Need It Now | G29: =IFERROR(VLOOKUP("Does Not Need It Now", Pivot!$A$2:$B$4842, 2, FALSE), 0) -> 0
B30: Customer drop | C30: =IFERROR(VLOOKUP("Customer drop", Pivot!$A$2:$B$4842, 2, FALSE), 0) -> 0 | F30: Technical Issue | G30: =IFERROR(VLOOKUP("Technical Issue", Pivot!$A$2:$B$4842, 2, FALSE), 0) -> 0
B31: Auto Dial Disconnected | C31: =IFERROR(VLOOKUP("Auto Dial Disconnected", Pivot!$A$2:$B$4842, 2, FALSE), 0) -> 0 | F31: Unsuccessful Application | G31: =IFERROR(VLOOKUP("Unsuccessful Application", Pivot!$A$2:$B$4842, 2, FALSE), 0) -> 0
B32: Disconnected Number Temporary | C32: =IFERROR(VLOOKUP("Disconnected Number Temporary", Pivot!$A$2:$B$4842, 2, FALSE), 0) -> 0
A35: TOTAL LEADS DIALLED | B35: =SUM(C6:C31)+SUM(E6:E9) -> 0
A37: CAMPAIGN STATISTICS
A38: Successful Contacts | B38: =SUM(E6:E9) -> 0
A39: True Contacts (TC) | B39: =SUM(I6:I19) -> 0
A40: Unworkable Leads | B40: =SUM(G6:G30) -> 0
A41: Conversions | B41: =E6 -> 0
A42: Conversion Ratio (vs TC) | B42: =B38/B37 -> 0
A43: Contact Ratio | B43: =(B37+B38)/B35 -> 0
A47: Top 5 Statuses | B47: Count | C47: % Contribution
A48: 13861083;0c5d0900-c88d-437b-a16f-855d45126772;;111111118;Vodacom Life 20260324;;;;;DROP;5;2026-05-22 | B48: 1 | C48: =B47/B35 -> 0
A49: 13861084;c5d4ca87-d640-4db8-b8be-7c1dd38b63af;;111111118;Vodacom Life 20260324;;;27606185640;;IABDN; | B49: 1 | C49: =B48/B35 -> 0
...
