Workbook

Sheet Pivot
A1: Row Labels | B1: Count of Description
A2: Answering Machine Autodial | B2: 4739
A3: No Answer Autodial | B3: 4418
A4: Callback | B4: 667
A5: Client Hung Up | B5: 550
A6: Not Interested | B6: 510
A7: Call Dropped | B7: 481
A8: Not Interested Upfront | B8: 454
A9: Unemployed | B9: 435
A10: Dropped | B10: 318
A11: Auto Engaged | B11: 315
A12: Wrong Number | B12: 303
A13: Selected | B13: 118
... A40: Grand Total | B40: 14245

Sheet Campaign Analysis
A1: Clientele Bellringer Leads Campaign Analysis
B5: Unsuccessful Contacts | C5: Lead Count | D5: Interested in Deal? | E5: Lead Count | F5: Successful Contacts | G5: Lead Count | H5: True Contacts | I5: Lead Count
B6: Answering Machine Autodial | C6: =IFERROR(VLOOKUP("Answering Machine Autodial", Pivot!$A$2:$B$39, 2, FALSE), 0) -> 0 | D6: Sale Made - Completed Mandate | E6: =IFERROR(VLOOKUP("Sale Made - Completed Mandate", Pivot!$A$2:$B$39, 2, FALSE), 0) -> 0 | F6: Already Contacted | G6: =IFERROR(VLOOKUP("Already Contacted", Pivot!$A$2:$B$39, 2, FALSE), 0) -> 0 | H6: Client Hung Up | I6: =IFERROR(VLOOKUP("Client Hung Up", Pivot!$A$2:$B$39, 2, FALSE), 0) -> 0
B7: No Answer Autodial | C7: =IFERROR(VLOOKUP("No Answer Autodial", Pivot!$A$2:$B$39, 2, FALSE), 0) -> 0 | D7: Sale Made - Pending Mandate | E7: =IFERROR(VLOOKUP("Sale Made - Pending Mandate", Pivot!$A$2:$B$39, 2, FALSE), 0) -> 0 | F7: Existing Client | G7: =IFERROR(VLOOKUP("Existing Client", Pivot!$A$2:$B$39, 2, FALSE), 0) -> 0 | H7: CallBack | I7: =IFERROR(VLOOKUP("CallBack", Pivot!$A$2:$B$39, 2, FALSE), 0) -> 0
B8: Auto Engaged | C8: =IFERROR(VLOOKUP("Auto Engaged", Pivot!$A$2:$B$39, 2, FALSE), 0) -> 0 | D8: Sale Made | E8: =IFERROR(VLOOKUP("Sale Made", Pivot!$A$2:$B$39, 2, FALSE), 0) -> 0 | F8: Unemployed | G8: =IFERROR(VLOOKUP("Unemployed", Pivot!$A$2:$B$39, 2, FALSE), 0) -> 0 | H8: Not Interested | I8: =IFERROR(VLOOKUP("Not Interested", Pivot!$A$2:$B$39, 2, FALSE), 0) -> 0
B9: Disconnected Number Auto | C9: =IFERROR(VLOOKUP("Disconnected Number Auto", Pivot!$A$2:$B$39, 2, FALSE), 0) -> 0 | D9: Tyme Bank Account Sale | E9: =IFERROR(VLOOKUP("Tyme Bank Account Sale", Pivot!$A$2:$B$39, 2, FALSE), 0) -> 0 | F9: Wrong Number | G9: =IFERROR(VLOOKUP("Wrong Number", Pivot!$A$2:$B$39, 2, FALSE), 0) -> 0 | H9: Not Interested Upfront | I9: =IFERROR(VLOOKUP("Not Interested Upfront", Pivot!$A$2:$B$39, 2, FALSE), 0) -> 0
B10: Answering Machine | C10: =IFERROR(VLOOKUP("Answering Machine", Pivot!$A$2:$B$39, 2, FALSE), 0) -> 0 | D10: QA Rework | E10: =IFERROR(VLOOKUP("QA Rework", Pivot!$A$2:$B$39, 2, FALSE), 0) -> 0 | F10: Do Not Call | G10: =IFERROR(VLOOKUP("Do Not Call", Pivot!$A$2:$B$39, 2, FALSE), 0) -> 0 | H10: Cannot Afford Premium | I10: =IFERROR(VLOOKUP("Cannot Afford Premium", Pivot!$A$2:$B$39, 2, FALSE), 0) -> 0
B11: Selected | C11: =IFERROR(VLOOKUP("Selected", Pivot!$A$2:$B$39, 2, FALSE), 0) -> 0 | F11: No Smartphones | G11: =IFERROR(VLOOKUP("No Smartphones", Pivot!$A$2:$B$39, 2, FALSE), 0) -> 0 | H11: Not interested - Pitched | I11: =IFERROR(VLOOKUP("Not interested - Pitched", Pivot!$A$2:$B$39, 2, FALSE), 0) -> 0
A12: TOTAL LEADS DIALLED | B12: =SUM(C6:C32)+SUM(E6:E10) -> 0 | C12: =IFERROR(VLOOKUP("No Answer", Pivot!$A$2:$B$39, 2, FALSE), 0) -> 0 | F12: Client Deceased | G12: =IFERROR(VLOOKUP("Client Deceased", Pivot!$A$2:$B$39, 2, FALSE), 0) -> 0 | H12: Affordability | I12: =IFERROR(VLOOKUP("Affordability", Pivot!$A$2:$B$39, 2, FALSE), 0) -> 0
B13: Busy Tone | C13: =IFERROR(VLOOKUP("Busy Tone", Pivot!$A$2:$B$39, 2, FALSE), 0) -> 0 | F13: Right Party Not Available | G13: =IFERROR(VLOOKUP("Right Party Not Available", Pivot!$A$2:$B$39, 2, FALSE), 0) -> 0 | H13: Quoted Client Not Interested | I13: =IFERROR(VLOOKUP("Quoted Client Not Interested", Pivot!$A$2:$B$39, 2, FALSE), 0) -> 0
B14: Dropped | C14: =IFERROR(VLOOKUP("Dropped", Pivot!$A$2:$B$39, 2, FALSE), 0) -> 0 | F14: Client Overage Limit | G14: =IFERROR(VLOOKUP("Client Overage Limit", Pivot!$A$2:$B$39, 2, FALSE), 0) -> 0 | H14: Not interested business does not use speed point mac | I14: =IFERROR(VLOOKUP("Not interested business does not use speed point mac", Pivot!$A$2:$B$39, 2, FALSE), 0) -> 0
B15: New | C15: =IFERROR(VLOOKUP("New", Pivot!$A$2:$B$39, 2, FALSE), 0) -> 0 | F15: Language Barrier | G15: =IFERROR(VLOOKUP("Language Barrier", Pivot!$A$2:$B$39, 2, FALSE), 0) -> 0 | H15: Call Back Technical Error | I15: =IFERROR(VLOOKUP("Call Back Technical Error", Pivot!$A$2:$B$39, 2, FALSE), 0) -> 0
B16: Call Dropped | C16: =IFERROR(VLOOKUP("Call Dropped", Pivot!$A$2:$B$39, 2, FALSE), 0) -> 0 | F16: Non SA Citizen | G16: =IFERROR(VLOOKUP("Non SA Citizen", Pivot!$A$2:$B$39, 2, FALSE), 0) -> 0 | H16: Not Interested Transaction Fees | I16: =IFERROR(VLOOKUP("Not Interested Transaction Fees", Pivot!$A$2:$B$39, 2, FALSE), 0) -> 0
B17: Inbound After Hours Drop | C17: =IFERROR(VLOOKUP("Inbound After Hours Drop", Pivot!$A$2:$B$39, 2, FALSE), 0) -> 0 | F17: No Bank Account | G17: =IFERROR(VLOOKUP("No Bank Account", Pivot!$A$2:$B$39, 2, FALSE), 0) -> 0 | H17: Cannot Afford | I17: =IFERROR(VLOOKUP("Cannot Afford", Pivot!$A$2:$B$39, 2, FALSE), 0) -> 0
B18: TPS Registered Number | C18: =IFERROR(VLOOKUP("TPS Registered Number", Pivot!$A$2:$B$39, 2, FALSE), 0) -> 0 | F18: Client Underage | G18: =IFERROR(VLOOKUP("Client Underage", Pivot!$A$2:$B$39, 2, FALSE), 0) -> 0 | H18: Not Interested Household Contents | I18: =IFERROR(VLOOKUP("Not Interested Household Contents", Pivot!$A$2:$B$39, 2, FALSE), 0) -> 0
B19: Temporary Disconnected Number | C19: =IFERROR(VLOOKUP("Temporary Disconnected Number", Pivot!$A$2:$B$39, 2, FALSE), 0) -> 0 | F19: Go To The Branch | G19: =IFERROR(VLOOKUP("Go To The Branch", Pivot!$A$2:$B$39, 2, FALSE), 0) -> 0 | H19: Call Back Hold | I19: =IFERROR(VLOOKUP("Call Back Hold", Pivot!$A$2:$B$39, 2, FALSE), 0) -> 0
B20: Bad Line Quality | C20: =IFERROR(VLOOKUP("Bad Line Quality", Pivot!$A$2:$B$39, 2, FALSE), 0) -> 0 | F20: Completed | G20: =IFERROR(VLOOKUP("Completed", Pivot!$A$2:$B$39, 2, FALSE), 0) -> 0 | H20: Declined Sale | I20: =IFERROR(VLOOKUP("Declined Sale", Pivot!$A$2:$B$39, 2, FALSE), 0) -> 0
B21: Inbound Abandon | C21: =IFERROR(VLOOKUP("Inbound Abandon", Pivot!$A$2:$B$39, 2, FALSE), 0) -> 0 | F21: Cannot Afford Upfront Payment | G21: =IFERROR(VLOOKUP("Cannot Afford Upfront Payment", Pivot!$A$2:$B$39, 2, FALSE), 0) -> 0
B22: Outbound Pre-Routing Drop | C22: =IFERROR(VLOOKUP("Outbound Pre-Routing Drop", Pivot!$A$2:$B$39, 2, FALSE), 0) -> 0 | F22: Account Suspended | G22: =IFERROR(VLOOKUP("Account Suspended", Pivot!$A$2:$B$39, 2, FALSE), 0) -> 0
B23: Engaged | C23: =IFERROR(VLOOKUP("Engaged", Pivot!$A$2:$B$39, 2, FALSE), 0) -> 0 | F23: Insured at another company | G23: =IFERROR(VLOOKUP("Insured at another company", Pivot!$A$2:$B$39, 2, FALSE), 0) -> 0
B24: Disconnected | C24: =IFERROR(VLOOKUP("Disconnected", Pivot!$A$2:$B$39, 2, FALSE), 0) -> 0 | F24: Scheduled Appointment | G24: =IFERROR(VLOOKUP("Scheduled Appointment", Pivot!$A$2:$B$39, 2, FALSE), 0) -> 0
B25: CONGESTED | C25: =IFERROR(VLOOKUP("CONGESTED", Pivot!$A$2:$B$39, 2, FALSE), 0) -> 0 | F25: Refund Request | G25: =IFERROR(VLOOKUP("Refund Request", Pivot!$A$2:$B$39, 2, FALSE), 0) -> 0
B26: Flow Inbound Abandon | C26: =IFERROR(VLOOKUP("Flow Inbound Abandon", Pivot!$A$2:$B$39, 2, FALSE), 0) -> 0 | F26: Does Not Qualify | G26: =IFERROR(VLOOKUP("Does Not Qualify", Pivot!$A$2:$B$39, 2, FALSE), 0) -> 0
B27: Multiple Calls | C27: =IFERROR(VLOOKUP("Multiple Calls", Pivot!$A$2:$B$39, 2, FALSE), 0) -> 0 | F27: Does Not Have a Business | G27: =IFERROR(VLOOKUP("Does Not Have a Business", Pivot!$A$2:$B$39, 2, FALSE), 0) -> 0
B28: Missed | C28: =IFERROR(VLOOKUP("Missed", Pivot!$A$2:$B$39, 2, FALSE), 0) -> 0 | F28: Refer To Store - Doesn't want to complete online | G28: =IFERROR(VLOOKUP("Refer To Store - Doesn't want to complete online", Pivot!$A$2:$B$39, 2, FALSE), 0) -> 0
B29: Answered | C29: =IFERROR(VLOOKUP("Answered", Pivot!$A$2:$B$39, 2, FALSE), 0) -> 0 | F29: Does Not Need It Now | G29: =IFERROR(VLOOKUP("Does Not Need It Now", Pivot!$A$2:$B$39, 2, FALSE), 0) -> 0
B30: Customer drop | C30: =IFERROR(VLOOKUP("Customer drop", Pivot!$A$2:$B$39, 2, FALSE), 0) -> 0 | F30: Technical Issue | G30: =IFERROR(VLOOKUP("Technical Issue", Pivot!$A$2:$B$39, 2, FALSE), 0) -> 0
B31: Auto Dial Disconnected | C31: =IFERROR(VLOOKUP("Auto Dial Disconnected", Pivot!$A$2:$B$39, 2, FALSE), 0) -> 0 | F31: Unsuccessful Application | G31: =IFERROR(VLOOKUP("Unsuccessful Application", Pivot!$A$2:$B$39, 2, FALSE), 0) -> 0
B32: Disconnected Number Temporary | C32: =IFERROR(VLOOKUP("Disconnected Number Temporary", Pivot!$A$2:$B$39, 2, FALSE), 0) -> 0
A37: CAMPAIGN STATISTICS
A38: Successful Contacts | B38: =SUM(E6:E10) -> 0
A39: True Contacts (TC) | B39: =SUM(I6:I20) -> 0
A40: Unworkable Leads | B40: =SUM(G6:G31) -> 0
A41: Conversions | B41: =E6 -> 0
A42: Conversion Ratio (vs TC) | B42: =B41/B39 -> 0
A43: Contact Ratio | B43: =(B38+B39)/B12 -> 0
A47: Top 5 Statuses | B47: Count | C47: % Contributor
A48: Answering Machine Autodial | B48: 4739 | C48: =B48/B12 -> 0
A49: No Answer Autodial | B49: 4418 | C49: =B49/B12 -> 0
A50: Callback | B50: 667 | C50: =B50/B12 -> 0
...
