Workbook

Sheet Processed Data
A1: Contact Id | B1: Customer Id | C1: Lead Reference | D1: List Id | E1: List Name | F1: Title | G1: Firstname | H1: Lastname | I1: Gender | J1: Last Outcome | K1: Outcome Description | L1: Called Count | M1: Last Called Date | N1: Last User | O1: Created At | P1: Updated At | Q1: Address1 | R1: Address2 | S1: Address3 | T1: Town | U1: County | V1: Country | W1: Postcode | X1: Email Address | Y1: Tel1 | Z1: Tel2 | AA1: Tel3 | AB1: Tel4 | AC1: Tel5 | AD1: Tel6 | AE1: Owner Username | AF1: Security Phrase | AG1: Source Reference | AH1: Industry | AI1: Company Name | AJ1: Website | AK1: Customer Reference | AL1: Dob
A2: 14921284 | B2: dfe3a969-a3f2-41f5-bfb3-801228643f48 | D2: 111111124 | E2: Vodacom Life 20260617 | G2: OLANEA | H2: NKOSI | J2: AFTHRS | K2: Inbound After Hours Drop | L2: 5 | M2: 2026-06-29 16:57:27 | N2: system | O2: 2026-06-17 14:10:06 | P2: 2026-06-17 14:10:06 | Y2: 27723249819
A3: 14921410 | B3: 2035c09e-7329-44e0-a1b4-9d0cb411aee6 | D3: 111111124 | E3: Vodacom Life 20260617 | G3: ROFHIWA | H3: MUNGONI | J3: IABDN | K3: Inbound Abandon | L3: 5 | M3: 2026-06-29 15:48:44 | N3: system | O3: 2026-06-17 14:10:06 | P3: 2026-06-17 14:10:06 | Y3: 27727696604
A4: 14921563 | B4: 355351aa-e300-4e6d-82a3-d977b45c7dc4 | D4: 111111124 | E4: Vodacom Life 20260617 | G4: COENRAAD | H4: NOLTE | J4: IABDN | K4: Inbound Abandon | L4: 5 | M4: 2026-06-29 15:37:34 | N4: system | O4: 2026-06-17 14:10:06 | P4: 2026-06-17 14:10:06 | Y4: 27661882064
A5: 14921581 | B5: f159181a-07e9-4e59-889c-4f4b88b5c2e7 | D5: 111111124 | E5: Vodacom Life 20260617 | G5: NOXOLO | H5: MDLALOSE | J5: CU | K5: Client Hung Up | L5: 5 | M5: 2026-06-29 14:49:14 | N5: Vanessa Kekana | O5: 2026-06-17 14:10:06 | P5: 2026-06-17 14:10:06 | Y5: 27795015710
A6: 14920658 | B6: ea95f004-7b39-45e6-bd6d-2170bf7c6f28 | D6: 111111124 | E6: Vodacom Life 20260617 | G6: MADONNA | H6: MKHABA | J6: CCB | K6: Call Dropped | L6: 5 | M6: 2026-06-29 14:46:16 | N6: Khensane Mabasa | O6: 2026-06-17 14:10:06 | P6: 2026-06-17 14:10:06 | Y6: 27728341837
A7: 14921291 | B7: bfa58c59-7660-4a56-92ac-c263464f7bac | D7: 111111124 | E7: Vodacom Life 20260617 | G7: THEMBISO | H7: DUBE | J7: CU | K7: Client Hung Up | L7: 6 | M7: 2026-06-29 14:41:04 | N7: Khensane Mabasa | O7: 2026-06-17 14:10:06 | P7: 2026-06-17 14:10:06 | Y7: 27762823602
A8: 14921565 | B8: a715c11d-b14b-4a3a-bcca-73276d7a45d2 | D8: 111111124 | E8: Vodacom Life 20260617 | G8: ROSELINA | H8: NTHOLENG | J8: IABDN | K8: Inbound Abandon | L8: 5 | M8: 2026-06-29 14:38:38 | N8: system | O8: 2026-06-17 14:10:06 | P8: 2026-06-17 14:10:06 | Y8: 27734693701
A9: 14921593 | B9: f4a2efc3-5980-42f2-bdde-73d0be5029e0 | D9: 111111124 | E9: Vodacom Life 20260617 | G9: WELCOME | H9: MASEKO | J9: IABDN | K9: Inbound Abandon | L9: 5 | M9: 2026-06-29 14:35:50 | N9: system | O9: 2026-06-17 14:10:06 | P9: 2026-06-17 14:10:06 | Y9: 27716178741
A10: 14921769 | B10: ee548fbf-2b50-4d15-af18-f7f4d0dc32fc | D10: 111111124 | E10: Vodacom Life 20260617 | G10: JAPPIE | H10: MATSHIA | J10: AC | K10: Already Contacted | L10: 4 | M10: 2026-06-29 14:27:05 | N10: Maureen Ntsoko | O10: 2026-06-17 14:10:06 | P10: 2026-06-17 14:10:06 | Y10: 27607280452
A11: 14921622 | B11: 9b91b38d-a240-412a-968e-418a1a57d2f4 | D11: 111111124 | E11: Vodacom Life 20260617 | G11: KAMOGELO | H11: VISAGIE | J11: CB | K11: Busy Tone | L11: 6 | M11: 2026-06-29 14:26:18 | N11: Maureen Ntsoko | O11: 2026-06-17 14:10:06 | P11: 2026-06-17 14:10:06 | Y11: 27608491456
A12: 14920678 | B12: c397bea7-6357-48ee-8def-1e589b2b5794 | D12: 111111124 | E12: Vodacom Life 20260617 | G12: GOITSIMANG | H12: MOELETSI | J12: A | K12: Answering Machine | L12: 9 | M12: 2026-06-29 14:25:15 | N12: Maureen Ntsoko | O12: 2026-06-17 14:10:06 | P12: 2026-06-17 14:10:06 | Y12: 27767833453
A13: 14920594 | B13: c0769749-8fdc-474c-8cd2-326c4e4440f6 | D13: 111111124 | E13: Vodacom Life 20260617 | G13: MAKUZE | H13: PEZA | J13: NI | K13: Not Interested | L13: 2 | M13: 2026-06-29 14:23:15 | N13: Maureen Ntsoko | O13: 2026-06-17 14:10:06 | P13: 2026-06-17 14:10:06 | Y13: 27762451526
... A1498: 14920807 | B1498: 391ce669-5fed-4c06-bf07-2c8b71260fea | D1498: 111111124 | E1498: Vodacom Life 20260617 | G1498: BHEKI | H1498: HADEBE | J1498: WN | K1498: Wrong Number | L1498: 2 | M1498: 2026-06-17 14:46:56 | N1498: Maureen Ntsoko | O1498: 2026-06-17 14:10:06 | P1498: 2026-06-17 14:10:06 | Y1498: 27676948334
A1499: 14921548 | B1499: e4c3d6ec-a9f4-4830-9ca5-30448233bb55 | D1499: 111111124 | E1499: Vodacom Life 20260617 | G1499: ARTHRO | H1499: PETERSEN | J1499: SELECTED | K1499: Selected | L1499: 1 | O1499: 2026-06-17 14:10:06 | P1499: 2026-06-17 14:10:06 | Y1499: 27796919283
A1500: 14921558 | D1500: 111111124 | E1500: Vodacom Life 20260617 | G1500: CYNTHIA | H1500: SCHEEPERS | J1500: None | K1500: New | L1500: 0 | O1500: 2026-06-17 14:10:06 | P1500: 2026-06-17 14:10:06 | Y1500: 27637774457
A1501: 14900000 | B1501: 8218060e-8155-4646-b7b5-b6317a212ef8 | D1501: 111111124 | E1501: Vodacom Life 20260617 | G1501: THABO | H1501: SITHOLE | J1501: SELECTED | K1501: Selected | L1501: 1 | O1501: 2026-06-17 14:10:06 | P1501: 2026-06-17 14:10:06 | Y1501: 27793116593

Sheet Sheet1
A1: Campaign:
A2: Product:
A6: total leads
A7: unworked leads (new leads)
A8: succesful contacts
A9: true contacts
A10: conversion
A11: true sales (post qa)
A12: Collections
A13: Number of missed 1st Collections
A14: NTU
A15: Cancellations/Lapse
... A179: Sale SMS

Sheet Campaign Analysis
A1: Campaign Analysis – Vodacom Life
A4: Total Leads | B4: 1500
A5: Unworked Leads (New Leads) | B5: 1
A6: Successful Contacts | B6: 275
A7: True Contacts | B7: 272
A8: Conversion | B8: 0.002
A9: True Sales (post QA) | B9: 3
B12: Unsuccessful Contacts | C12: Lead Count | D12: Interested in Deal? | E12: Lead Count | F12: Successful Contacts | G12: Lead Count | H12: True Contacts | I12: Lead Count
B13: Answering Machine Autodial | C13: =IFERROR(VLOOKUP("Answering Machine Autodial",Pivot!$A$2:$B$34,2,FALSE),0) | D13: Sale Made - Completed Mandate | E13: =IFERROR(VLOOKUP("Sale Made - Completed Mandate",Pivot!$A$2:$B$34,2,FALSE),0) | F13: Already Contacted | G13: =IFERROR(VLOOKUP("Already Contacted",Pivot!$A$2:$B$34,2,FALSE),0) | H13: Client Hung Up | I13: =IFERROR(VLOOKUP("Client Hung Up",Pivot!$A$2:$B$34,2,FALSE),0)
B14: No Answer Autodial | C14: =IFERROR(VLOOKUP("No Answer Autodial",Pivot!$A$2:$B$34,2,FALSE),0) | D14: Sale Made - Pending Mandate | E14: =IFERROR(VLOOKUP("Sale Made - Pending Mandate",Pivot!$A$2:$B$34,2,FALSE),0) | F14: Existing Client | G14: =IFERROR(VLOOKUP("Existing Client",Pivot!$A$2:$B$34,2,FALSE),0) | H14: CallBack | I14: =IFERROR(VLOOKUP("CallBack",Pivot!$A$2:$B$34,2,FALSE),0)
B15: Auto Engaged | C15: =IFERROR(VLOOKUP("Auto Engaged",Pivot!$A$2:$B$34,2,FALSE),0) | D15: Sale Made | E15: =IFERROR(VLOOKUP("Sale Made",Pivot!$A$2:$B$34,2,FALSE),0) | F15: Unemployed | G15: =IFERROR(VLOOKUP("Unemployed",Pivot!$A$2:$B$34,2,FALSE),0) | H15: Not Interested | I15: =IFERROR(VLOOKUP("Not Interested",Pivot!$A$2:$B$34,2,FALSE),0)
B16: Disconnected Number Auto | C16: =IFERROR(VLOOKUP("Disconnected Number Auto",Pivot!$A$2:$B$34,2,FALSE),0) | D16: Tyme Bank Account Sale | E16: =IFERROR(VLOOKUP("Tyme Bank Account Sale",Pivot!$A$2:$B$34,2,FALSE),0) | F16: Wrong Number | G16: =IFERROR(VLOOKUP("Wrong Number",Pivot!$A$2:$B$34,2,FALSE),0) | H16: Not Interested Upfront | I16: =IFERROR(VLOOKUP("Not Interested Upfront",Pivot!$A$2:$B$34,2,FALSE),0)
B17: Answering Machine | C17: =IFERROR(VLOOKUP("Answering Machine",Pivot!$A$2:$B$34,2,FALSE),0) | D17: QA Rework | E17: =IFERROR(VLOOKUP("QA Rework",Pivot!$A$2:$B$34,2,FALSE),0) | F17: Do Not Call | G17: =IFERROR(VLOOKUP("Do Not Call",Pivot!$A$2:$B$34,2,FALSE),0) | H17: Cannot Afford Premium | I17: =IFERROR(VLOOKUP("Cannot Afford Premium",Pivot!$A$2:$B$34,2,FALSE),0)
B18: Selected | C18: =IFERROR(VLOOKUP("Selected",Pivot!$A$2:$B$34,2,FALSE),0) | F18: No Smartphones | G18: =IFERROR(VLOOKUP("No Smartphones",Pivot!$A$2:$B$34,2,FALSE),0) | H18: Not interested - Pitched | I18: =IFERROR(VLOOKUP("Not interested - Pitched",Pivot!$A$2:$B$34,2,FALSE),0)
B19: No Answer | C19: =IFERROR(VLOOKUP("No Answer",Pivot!$A$2:$B$34,2,FALSE),0) | F19: Client Deceased | G19: =IFERROR(VLOOKUP("Client Deceased",Pivot!$A$2:$B$34,2,FALSE),0) | H19: Affordability | I19: =IFERROR(VLOOKUP("Affordability",Pivot!$A$2:$B$34,2,FALSE),0)
B20: Busy Tone | C20: =IFERROR(VLOOKUP("Busy Tone",Pivot!$A$2:$B$34,2,FALSE),0) | F20: Right Party Not Available | G20: =IFERROR(VLOOKUP("Right Party Not Available",Pivot!$A$2:$B$34,2,FALSE),0) | H20: Quoted Client Not Interested | I20: =IFERROR(VLOOKUP("Quoted Client Not Interested",Pivot!$A$2:$B$34,2,FALSE),0)
B21: Dropped | C21: =IFERROR(VLOOKUP("Dropped",Pivot!$A$2:$B$34,2,FALSE),0) | F21: Client Overage Limit | G21: =IFERROR(VLOOKUP("Client Overage Limit",Pivot!$A$2:$B$34,2,FALSE),0) | H21: Not interested business does not use speed point mac | I21: =IFERROR(VLOOKUP("Not interested business does not use speed point mac",Pivot!$A$2:$B$34,2,FALSE),0)
B22: New | C22: =IFERROR(VLOOKUP("New",Pivot!$A$2:$B$34,2,FALSE),0) | F22: Language Barrier | G22: =IFERROR(VLOOKUP("Language Barrier",Pivot!$A$2:$B$34,2,FALSE),0) | H22: Call Back Technical Error | I22: =IFERROR(VLOOKUP("Call Back Technical Error",Pivot!$A$2:$B$34,2,FALSE),0)
B23: Call Dropped | C23: =IFERROR(VLOOKUP("Call Dropped",Pivot!$A$2:$B$34,2,FALSE),0) | F23: Non SA Citizen | G23: =IFERROR(VLOOKUP("Non SA Citizen",Pivot!$A$2:$B$34,2,FALSE),0) | H23: Not Interested Transaction Fees | I23: =IFERROR(VLOOKUP("Not Interested Transaction Fees",Pivot!$A$2:$B$34,2,FALSE),0)
B24: Inbound After Hours Drop | C24: =IFERROR(VLOOKUP("Inbound After Hours Drop",Pivot!$A$2:$B$34,2,FALSE),0) | F24: No Bank Account | G24: =IFERROR(VLOOKUP("No Bank Account",Pivot!$A$2:$B$34,2,FALSE),0) | H24: Cannot Afford | I24: =IFERROR(VLOOKUP("Cannot Afford",Pivot!$A$2:$B$34,2,FALSE),0)
B25: TPS Registered Number | C25: =IFERROR(VLOOKUP("TPS Registered Number",Pivot!$A$2:$B$34,2,FALSE),0) | F25: Client Underage | G25: =IFERROR(VLOOKUP("Client Underage",Pivot!$A$2:$B$34,2,FALSE),0) | H25: Not Interested Household Contents | I25: =IFERROR(VLOOKUP("Not Interested Household Contents",Pivot!$A$2:$B$34,2,FALSE),0)
B26: Temporary Disconnected Number | C26: =IFERROR(VLOOKUP("Temporary Disconnected Number",Pivot!$A$2:$B$34,2,FALSE),0) | F26: Go To The Branch | G26: =IFERROR(VLOOKUP("Go To The Branch",Pivot!$A$2:$B$34,2,FALSE),0) | H26: Call Back Hold | I26: =IFERROR(VLOOKUP("Call Back Hold",Pivot!$A$2:$B$34,2,FALSE),0)
B27: Bad Line Quality | C27: =IFERROR(VLOOKUP("Bad Line Quality",Pivot!$A$2:$B$34,2,FALSE),0) | F27: Completed | G27: =IFERROR(VLOOKUP("Completed",Pivot!$A$2:$B$34,2,FALSE),0) | H27: Declined Sale | I27: =IFERROR(VLOOKUP("Declined Sale",Pivot!$A$2:$B$34,2,FALSE),0)
B28: Inbound Abandon | C28: =IFERROR(VLOOKUP("Inbound Abandon",Pivot!$A$2:$B$34,2,FALSE),0) | F28: Cannot Afford Upfront Payment | G28: =IFERROR(VLOOKUP("Cannot Afford Upfront Payment",Pivot!$A$2:$B$34,2,FALSE),0)
B29: Outbound Pre-Routing Drop | C29: =IFERROR(VLOOKUP("Outbound Pre-Routing Drop",Pivot!$A$2:$B$34,2,FALSE),0) | F29: Account Suspended | G29: =IFERROR(VLOOKUP("Account Suspended",Pivot!$A$2:$B$34,2,FALSE),0)
B30: Engaged | C30: =IFERROR(VLOOKUP("Engaged",Pivot!$A$2:$B$34,2,FALSE),0) | F30: Insured at another company | G30: =IFERROR(VLOOKUP("Insured at another company",Pivot!$A$2:$B$34,2,FALSE),0)
B31: Disconnected | C31: =IFERROR(VLOOKUP("Disconnected",Pivot!$A$2:$B$34,2,FALSE),0) | F31: Scheduled Appointment | G31: =IFERROR(VLOOKUP("Scheduled Appointment",Pivot!$A$2:$B$34,2,FALSE),0)
B32: CONGESTED | C32: =IFERROR(VLOOKUP("CONGESTED",Pivot!$A$2:$B$34,2,FALSE),0) | F32: Refund Request | G32: =IFERROR(VLOOKUP("Refund Request",Pivot!$A$2:$B$34,2,FALSE),0)
B33: Flow Inbound Abandon | C33: =IFERROR(VLOOKUP("Flow Inbound Abandon",Pivot!$A$2:$B$34,2,FALSE),0) | F33: Does Not Qualify | G33: =IFERROR(VLOOKUP("Does Not Qualify",Pivot!$A$2:$B$34,2,FALSE),0)
B34: Multiple Calls | C34: =IFERROR(VLOOKUP("Multiple Calls",Pivot!$A$2:$B$34,2,FALSE),0) | F34: Does Not Have a Business | G34: =IFERROR(VLOOKUP("Does Not Have a Business",Pivot!$A$2:$B$34,2,FALSE),0)
B35: Missed | C35: =IFERROR(VLOOKUP("Missed",Pivot!$A$2:$B$34,2,FALSE),0) | F35: Refer To Store - Doesn't want to complete online | G35: =IFERROR(VLOOKUP("Refer To Store - Doesn't want to complete online",Pivot!$A$2:$B$34,2,FALSE),0)
B36: Answered | C36: =IFERROR(VLOOKUP("Answered",Pivot!$A$2:$B$34,2,FALSE),0) | F36: Does Not Need It Now | G36: =IFERROR(VLOOKUP("Does Not Need It Now",Pivot!$A$2:$B$34,2,FALSE),0)
B37: Customer drop | C37: =IFERROR(VLOOKUP("Customer drop",Pivot!$A$2:$B$34,2,FALSE),0) | F37: Technical Issue | G37: =IFERROR(VLOOKUP("Technical Issue",Pivot!$A$2:$B$34,2,FALSE),0)
B38: Auto Dial Disconnected | C38: =IFERROR(VLOOKUP("Auto Dial Disconnected",Pivot!$A$2:$B$34,2,FALSE),0) | F38: Unsuccessful Application | G38: =IFERROR(VLOOKUP("Unsuccessful Application",Pivot!$A$2:$B$34,2,FALSE),0)
B39: Disconnected Number Temporary | C39: =IFERROR(VLOOKUP("Disconnected Number Temporary",Pivot!$A$2:$B$34,2,FALSE),0)
A42: TOTAL LEADS DIALLED | B42: =SUM(C13:C39)+SUM(E13:E17)
A44: CAMPAIGN STATISTICS
A45: Successful Contacts | B45: =SUM(F13:F17)
A46: True Contacts (TC) | B46: =SUM(I13:I27)
A47: Unworkable Leads | B47: =SUM(G13:G38)
...

Sheet Pivot
A1: Outcome Description | B1: Count
A2: Answering Machine Autodial | B2: 372
A3: Auto Engaged | B3: 288
A4: Dropped | B4: 170
A5: No Answer Autodial | B5: 143
A6: Not Interested | B6: 88
A7: Callback | B7: 83
A8: Client Hung Up | B8: 79
A9: Auto Dial Disconnected | B9: 45
A10: Already Contacted | B10: 31
A11: Answering Machine | B11: 30
A12: Inbound Abandon | B12: 25
A13: Unemployed | B13: 22
... A35: Grand Total | B35: 1500
