Workbook

Sheet Sheet1
A1: Campaign:
A2: Product:
A6: total leads
A7: unworked leads (new leads)
A8: succesful contacts
A9: true contacts
A10: conversion
A11: true sales (post qa)
A12: Collections
A13: Number of missed 1st Collections
A14: NTU
A15: Cancellations/Lapse
... A179: Sale SMS

Sheet Pivot_Data
A1: Outcome Description | B1: Count
A2: Answering Machine Autodial | B2: 247
A3: Auto Engaged | B3: 178
A4: Dropped | B4: 94
A5: No Answer Autodial | B5: 92
A6: Callback | B6: 69
A7: Client Hung Up | B7: 59
A8: Not Interested | B8: 42
A9: Inbound Abandon | B9: 40
A10: Already Contacted | B10: 28
A11: Auto Dial Disconnected | B11: 28
A12: Unemployed | B12: 20
A13: Answering Machine | B13: 17
... A31: Grand Total | B31: 1000

Sheet Processed Data
A1: Contact Id | B1: Customer Id | C1: Lead Reference | D1: List Id | E1: List Name | F1: Title | G1: Firstname | H1: Lastname | I1: Gender | J1: Last Outcome | K1: Outcome Description | L1: Called Count | M1: Last Called Date | N1: Last User | O1: Created At | P1: Updated At | Q1: Address1 | R1: Address2 | S1: Address3 | T1: Town | U1: County | V1: Country | W1: Postcode | X1: Email Address | Y1: Tel1 | Z1: Tel2 | AA1: Tel3 | AB1: Tel4 | AC1: Tel5 | AD1: Tel6 | AE1: Owner Username | AF1: Security Phrase | AG1: Source Reference | AH1: Industry | AI1: Company Name | AJ1: Website | AK1: Customer Reference | AL1: Dob
A2: 14828504 | B2: c98ebd33-cac2-4aab-8bab-6b45e8bfbed9 | D2: 111111123 | E2: Vodacom Life 20260603 | H2: 27766792170 | J2: A | K2: Answering Machine | L2: 8 | M2: 2026-06-26 11:37:47 | N2: Musiiwa Mary Mabirimisa | O2: 2026-06-08 05:25:27 | P2: 2026-06-08 05:25:27 | Y2: 27766792170
A3: 14828124 | B3: ad5efd52-c734-4b8d-9f17-6eb51eacd3fb | D3: 111111123 | E3: Vodacom Life 20260603 | H3: 27664322996 | J3: CCB | K3: Call Dropped | L3: 7 | M3: 2026-06-25 14:42:17 | N3: Musiiwa Mary Mabirimisa | O3: 2026-06-08 05:25:27 | P3: 2026-06-08 05:25:27 | Y3: 27664322996
A4: 14828442 | B4: 18632b8d-b536-47b5-8bc2-18cd6f00e239 | D4: 111111123 | E4: Vodacom Life 20260603 | J4: DNQS | K4: Does Not Qualify | L4: 8 | M4: 2026-06-25 12:51:19 | N4: Musiiwa Mary Mabirimisa | O4: 2026-06-08 05:25:27 | P4: 2026-06-08 05:25:27 | Y4: 27765613766
A5: 14828311 | B5: eff62591-c93c-4177-aa9a-1071272795e4 | D5: 111111123 | E5: Vodacom Life 20260603 | J5: CCB | K5: Call Dropped | L5: 9 | M5: 2026-06-25 12:32:48 | N5: Musiiwa Mary Mabirimisa | O5: 2026-06-08 05:25:27 | P5: 2026-06-08 05:25:27 | Y5: 27760867339
A6: 14828262 | B6: 89032e70-1768-4bd0-813c-a8efb57640cf | D6: 111111123 | E6: Vodacom Life 20260603 | J6: N | K6: No Answer | L6: 8 | M6: 2026-06-25 09:17:10 | N6: Musiiwa Mary Mabirimisa | O6: 2026-06-08 05:25:27 | P6: 2026-06-08 05:25:27 | Y6: 27820448179
A7: 14827781 | B7: cdf34d13-c4e2-4d1e-92c5-0359e3ca27f3 | D7: 111111123 | E7: Vodacom Life 20260603 | H7: 27726379764 | J7: IABDN | K7: Inbound Abandon | L7: 7 | M7: 2026-06-24 16:16:58 | N7: system | O7: 2026-06-08 05:25:27 | P7: 2026-06-08 05:25:27 | Y7: 27726379764
A8: 14827590 | B8: 845da16b-28ff-44a6-a1a8-fa9110ad60b2 | D8: 111111123 | E8: Vodacom Life 20260603 | J8: A | K8: Answering Machine | L8: 13 | M8: 2026-06-24 14:34:49 | N8: Maureen Ntsoko | O8: 2026-06-08 05:25:27 | P8: 2026-06-08 05:25:27 | Y8: 27715476499
A9: 14828156 | B9: 6010c971-6a0a-47eb-9a7b-8c4a8355d682 | D9: 111111123 | E9: Vodacom Life 20260603 | J9: CB | K9: Busy Tone | L9: 7 | M9: 2026-06-24 10:35:45 | N9: Musiiwa Mary Mabirimisa | O9: 2026-06-08 05:25:27 | P9: 2026-06-08 05:25:27 | Y9: 27798486924
A10: 14828196 | B10: 048c1fac-7f0f-4891-b1c2-cece9e1b360a | D10: 111111123 | E10: Vodacom Life 20260603 | J10: A | K10: Answering Machine | L10: 7 | M10: 2026-06-24 08:47:54 | N10: Musiiwa Mary Mabirimisa | O10: 2026-06-08 05:25:27 | P10: 2026-06-08 05:25:27 | Y10: 27768963240
A11: 14828161 | B11: 519a5d80-520e-4d20-9c8b-123fc3ee4e06 | D11: 111111123 | E11: Vodacom Life 20260603 | H11: 27772939778 | J11: N | K11: No Answer | L11: 7 | M11: 2026-06-24 06:41:33 | N11: Musiiwa Mary Mabirimisa | O11: 2026-06-08 05:25:27 | P11: 2026-06-08 05:25:27 | Y11: 27772939778
A12: 14827670 | B12: f11b3b84-d4f6-40c3-af01-12d0ca050361 | D12: 111111123 | E12: Vodacom Life 20260603 | H12: 27792803613 | J12: N | K12: No Answer | L12: 9 | M12: 2026-06-24 06:35:14 | N12: Musiiwa Mary Mabirimisa | O12: 2026-06-08 05:25:27 | P12: 2026-06-08 05:25:27 | Y12: 27792803613
A13: 14827596 | B13: 16d97988-78c6-4893-ad9b-ab24d06075a4 | D13: 111111123 | E13: Vodacom Life 20260603 | J13: CB | K13: Busy Tone | L13: 8 | M13: 2026-06-19 12:28:08 | N13: Khensane Mabasa | O13: 2026-06-08 05:25:27 | P13: 2026-06-08 05:25:27 | Y13: 27721176606
A14: 14828235 | B14: d1f5323a-84f2-4043-88b3-2dd33b6ec555 | D14: 111111123 | E14: Vodacom Life 20260603 | H14: 27722575370 | J14: CU | K14: Client Hung Up | L14: 24 | M14: 2026-06-19 10:10:46 | N14: Maureen Ntsoko | O14: 2026-06-08 05:25:27 | P14: 2026-06-08 05:25:27 | Y14: 27722575370
A15: 14828253 | B15: 4e15dfd4-9699-4563-8016-6be35ed24a2a | D15: 111111123 | E15: Vodacom Life 20260603 | J15: DNQS | K15: Does Not Qualify | L15: 4 | M15: 2026-06-19 09:45:27 | N15: Maureen Ntsoko | O15: 2026-06-08 05:25:27 | P15: 2026-06-08 05:25:27 | Y15: 27767763940
A16: 14828147 | B16: 7a0be475-e936-4ac0-a21d-1287dd98f7af | D16: 111111123 | E16: Vodacom Life 20260603 | J16: AC | K16: Already Contacted | L16: 12 | M16: 2026-06-19 07:47:34 | N16: Maureen Ntsoko | O16: 2026-06-08 05:25:27 | P16: 2026-06-08 05:25:27 | Y16: 27768097817
A17: 14828344 | B17: c52866d2-654b-463b-95db-40d300b08610 | D17: 111111123 | E17: Vodacom Life 20260603 | J17: CB | K17: Busy Tone | L17: 8 | M17: 2026-06-19 07:33:41 | N17: Maureen Ntsoko | O17: 2026-06-08 05:25:27 | P17: 2026-06-08 05:25:27 | Y17: 27722228317
A18: 14828212 | B18: ecfe4295-2479-4ce9-8c17-c2cf6acb58c2 | D18: 111111123 | E18: Vodacom Life 20260603 | J18: N | K18: No Answer | L18: 13 | M18: 2026-06-18 07:53:05 | N18: Maureen Ntsoko | O18: 2026-06-08 05:25:27 | P18: 2026-06-08 05:25:27 | Y18: 27674612571
A19: 14828479 | B19: 62f5c396-0b0b-49c4-84f6-a67529dbce27 | D19: 111111123 | E19: Vodacom Life 20260603 | H19: 27768752354 | J19: IABDN | K19: Inbound Abandon | L19: 7 | M19: 2026-06-17 15:08:27 | N19: system | O19: 2026-06-08 05:25:27 | P19: 2026-06-08 05:25:27 | Y19: 27768752354
A20: 14828003 | B20: 80cf1ebc-a3b5-4d9e-ac86-40d5001f3c16 | D20: 111111123 | E20: Vodacom Life 20260603 | H20: 27825812643 | J20: IABDN | K20: Inbound Abandon | L20: 10 | M20: 2026-06-17 14:52:44 | N20: system | O20: 2026-06-08 05:25:27 | P20: 2026-06-08 05:25:27 | Y20: 27825812643
A21: 14828454 | B21: 5ec6e30a-54ad-40d1-88b6-ec9c251e51d6 | D21: 111111123 | E21: Vodacom Life 20260603 | H21: 27660738189 | J21: IABDN | K21: Inbound Abandon | L21: 8 | M21: 2026-06-17 13:23:59 | N21: system | O21: 2026-06-08 05:25:27 | P21: 2026-06-08 05:25:27 | Y21: 27660738189
A22: 14828119 | B22: bf6b21ac-b092-4064-ac36-c510c5b708b7 | D22: 111111123 | E22: Vodacom Life 20260603 | J22: AC | K22: Already Contacted | L22: 9 | M22: 2026-06-17 10:53:42 | N22: Maureen Ntsoko | O22: 2026-06-08 05:25:27 | P22: 2026-06-08 05:25:27 | Y22: 27798477722
A23: 14827569 | B23: 4b575512-1a1d-4540-9f7b-cb62cfc6f3ba | D23: 111111123 | E23: Vodacom Life 20260603 | H23: 27792437200 | J23: DQQD | K23: DNQ Quote Declined | L23: 7 | M23: 2026-06-17 09:22:38 | N23: Khensane Mabasa | O23: 2026-06-08 05:25:27 | P23: 2026-06-08 05:25:27 | Y23: 27792437200
A24: 14827878 | B24: 41def82a-d3d3-4336-9b95-00675d611bdf | D24: 111111123 | E24: Vodacom Life 20260603 | H24: 27760440000 | J24: IABDN | K24: Inbound Abandon | L24: 7 | M24: 2026-06-17 08:03:49 | N24: system | O24: 2026-06-08 05:25:27 | P24: 2026-06-08 05:25:27 | Y24: 27760440000
A25: 14827723 | B25: 1d7739d3-8518-40e5-bbc3-f101dbeaa786 | D25: 111111123 | E25: Vodacom Life 20260603 | J25: N | K25: No Answer | L25: 8 | M25: 2026-06-17 07:10:21 | N25: Khensane Mabasa | O25: 2026-06-08 05:25:27 | P25: 2026-06-08 05:25:27 | Y25: 27711878675
A26: 14827558 | B26: bbc467ab-2f43-4c3c-9e1a-3a8416b3aa1b | D26: 111111123 | E26: Vodacom Life 20260603 | J26: QAVET | K26: Sale Made | L26: 8 | M26: 2026-06-17 07:09:51 | N26: Maureen Ntsoko | O26: 2026-06-08 05:25:27 | P26: 2026-06-08 05:25:27 | Y26: 27716258698
A27: 14828218 | B27: 92ff0850-7d5a-40bd-a879-22d95b32da2f | D27: 111111123 | E27: Vodacom Life 20260603 | H27: 27711923928 | J27: DROP | K27: Dropped | L27: 7 | M27: 2026-06-17 06:02:31 | N27: system | O27: 2026-06-08 05:25:27 | P27: 2026-06-08 05:25:27 | Y27: 27711923928
A28: 14828488 | B28: 05715555-3b20-4e7e-9334-b0db9750e2ef | D28: 111111123 | E28: Vodacom Life 20260603 | H28: 27712861433 | J28: DROP | K28: Dropped | L28: 7 | M28: 2026-06-17 06:02:31 | N28: system | O28: 2026-06-08 05:25:27 | P28: 2026-06-08 05:25:27 | Y28: 27712861433
A29: 14828357 | B29: 2edefb7a-378f-4f61-9624-07f8b9362d1b | D29: 111111123 | E29: Vodacom Life 20260603 | H29: 27761406482 | J29: AFTHRS | K29: Inbound After Hours Drop | L29: 7 | M29: 2026-06-15 16:57:44 | N29: system | O29: 2026-06-08 05:25:27 | P29: 2026-06-08 05:25:27 | Y29: 27761406482
A30: 14827875 | B30: a6ff25f8-1cad-4cff-8b7a-c7e86b8cf855 | D30: 111111123 | E30: Vodacom Life 20260603 | H30: 27823403672 | J30: CU | K30: Client Hung Up | L30: 7 | M30: 2026-06-15 14:27:33 | N30: Maureen Ntsoko | O30: 2026-06-08 05:25:27 | P30: 2026-06-08 05:25:27 | Y30: 27823403672
A31: 14828511 | B31: 760cb91f-403f-4fb0-8bf0-e432f02cef7c | D31: 111111123 | E31: Vodacom Life 20260603 | H31: 27763802950 | J31: IABDN | K31: Inbound Abandon | L31: 7 | M31: 2026-06-15 12:08:43 | N31: system | O31: 2026-06-08 05:25:27 | P31: 2026-06-08 05:25:27 | Y31: 27763802950
A32: 14827918 | B32: 96538359-9716-4944-95ab-c05dc92678b4 | D32: 111111123 | E32: Vodacom Life 20260603 | J32: AA | K32: Answering Machine Autodial | L32: 7 | M32: 2026-06-15 10:22:05 | N32: system | O32: 2026-06-08 05:25:27 | P32: 2026-06-08 05:25:27 | Y32: 27646271120
A33: 14828036 | B33: 0051cb9f-db48-4fb5-af63-d9a523664611 | D33: 111111123 | E33: Vodacom Life 20260603 | H33: 27799968911 | J33: IABDN | K33: Inbound Abandon | L33: 7 | M33: 2026-06-15 09:58:35 | N33: system | O33: 2026-06-08 05:25:27 | P33: 2026-06-08 05:25:27 | Y33: 27799968911
A34: 14827629 | B34: 21640b7c-8e82-4f1d-9e7c-78445d47b9eb | D34: 111111123 | E34: Vodacom Life 20260603 | H34: 27607618682 | J34: A | K34: Answering Machine | L34: 7 | M34: 2026-06-15 09:44:43 | N34: bongiwe lushaba | O34: 2026-06-08 05:25:27 | P34: 2026-06-08 05:25:27 | Y34: 27607618682
A35: 14828256 | B35: 7645425c-591d-4e01-aeac-3484f3ef5fe2 | D35: 111111123 | E35: Vodacom Life 20260603 | H35: 27818063859 | J35: IABDN | K35: Inbound Abandon | L35: 7 | M35: 2026-06-15 09:43:00 | N35: system | O35: 2026-06-08 05:25:27 | P35: 2026-06-08 05:25:27 | Y35: 27818063859
A36: 14828314 | B36: 547f0a20-4631-4b53-93ee-654a5073b132 | D36: 111111123 | E36: Vodacom Life 20260603 | H36: 27609542682 | J36: AA | K36: Answering Machine Autodial | L36: 7 | M36: 2026-06-15 09:29:04 | N36: system | O36: 2026-06-08 05:25:27 | P36: 2026-06-08 05:25:27 | Y36: 27609542682
A37: 14828277 | B37: edba40e1-8f10-42f5-9d5e-db97c221ab03 | D37: 111111123 | E37: Vodacom Life 20260603 | H37: 27724531707 | J37: IABDN | K37: Inbound Abandon | L37: 8 | M37: 2026-06-15 09:27:00 | N37: system | O37: 2026-06-08 05:25:27 | P37: 2026-06-08 05:25:27 | Y37: 27724531707
A38: 14827681 | B38: 03a13c19-87ed-48ef-99de-1e3e779d5272 | D38: 111111123 | E38: Vodacom Life 20260603 | H38: 27729503424 | J38: IABDN | K38: Inbound Abandon | L38: 7 | M38: 2026-06-15 09:11:13 | N38: system | O38: 2026-06-08 05:25:27 | P38: 2026-06-08 05:25:27 | Y38: 27729503424
A39: 14828004 | B39: db45303d-9025-434e-9aa9-0d48501c13c7 | D39: 111111123 | E39: Vodacom Life 20260603 | J39: DROP | K39: Dropped | L39: 7 | M39: 2026-06-15 08:49:40 | N39: system | O39: 2026-06-08 05:25:27 | P39: 2026-06-08 05:25:27 | Y39: 27720949177
A40: 14828064 | B40: 456b3d34-1d03-44e2-9b21-8c4945d5d9d4 | D40: 111111123 | E40: Vodacom Life 20260603 | J40: AA | K40: Answering Machine Autodial | L40: 7 | M40: 2026-06-15 08:49:16 | N40: system | O40: 2026-06-08 05:25:27 | P40: 2026-06-08 05:25:27 | Y40: 27723663474
...

Sheet Campaign Analysis
A1: Campaign Analysis – Vodacom Life
A4: Total Leads | B4: 1000
A5: Unworked Leads (New Leads) | B5: 0
A6: Successful Contacts | B6: 187
A7: True Contacts | B7: 182
A8: Conversion | B8: 0.005
A9: True Sales (post QA) | B9: 5
A10: Collections
A11: Number of missed 1st Collections
A12: NTU
A13: Cancellations/Lapse
B16: Unsuccessful Contacts | C16: Lead Count | D16: Interested in Deal? | E16: Lead Count | F16: Successful Contacts | G16: Lead Count | H16: True Contacts | I16: Lead Count
B17: Answering Machine Autodial | C17: =IFERROR(VLOOKUP("Answering Machine Autodial",Pivot!$A$2:$B$30,2,FALSE),0) | D17: Sale Made - Completed Mandate | E17: =IFERROR(VLOOKUP("Sale Made - Completed Mandate",Pivot!$A$2:$B$30,2,FALSE),0) | F17: Already Contacted | G17: =IFERROR(VLOOKUP("Already Contacted",Pivot!$A$2:$B$30,2,FALSE),0) | H17: Client Hung Up | I17: =IFERROR(VLOOKUP("Client Hung Up",Pivot!$A$2:$B$30,2,FALSE),0)
B18: No Answer Autodial | C18: =IFERROR(VLOOKUP("No Answer Autodial",Pivot!$A$2:$B$30,2,FALSE),0) | D18: Sale Made - Pending Mandate | E18: =IFERROR(VLOOKUP("Sale Made - Pending Mandate",Pivot!$A$2:$B$30,2,FALSE),0) | F18: Existing Client | G18: =IFERROR(VLOOKUP("Existing Client",Pivot!$A$2:$B$30,2,FALSE),0) | H18: CallBack | I18: =IFERROR(VLOOKUP("CallBack",Pivot!$A$2:$B$30,2,FALSE),0)
B19: Auto Engaged | C19: =IFERROR(VLOOKUP("Auto Engaged",Pivot!$A$2:$B$30,2,FALSE),0) | D19: Sale Made | E19: =IFERROR(VLOOKUP("Sale Made",Pivot!$A$2:$B$30,2,FALSE),0) | F19: Unemployed | G19: =IFERROR(VLOOKUP("Unemployed",Pivot!$A$2:$B$30,2,FALSE),0) | H19: Not Interested | I19: =IFERROR(VLOOKUP("Not Interested",Pivot!$A$2:$B$30,2,FALSE),0)
B20: Disconnected Number Auto | C20: =IFERROR(VLOOKUP("Disconnected Number Auto",Pivot!$A$2:$B$30,2,FALSE),0) | D20: Tyme Bank Account Sale | E20: =IFERROR(VLOOKUP("Tyme Bank Account Sale",Pivot!$A$2:$B$30,2,FALSE),0) | F20: Wrong Number | G20: =IFERROR(VLOOKUP("Wrong Number",Pivot!$A$2:$B$30,2,FALSE),0) | H20: Not Interested Upfront | I20: =IFERROR(VLOOKUP("Not Interested Upfront",Pivot!$A$2:$B$30,2,FALSE),0)
B21: Answering Machine | C21: =IFERROR(VLOOKUP("Answering Machine",Pivot!$A$2:$B$30,2,FALSE),0) | D21: QA Rework | E21: =IFERROR(VLOOKUP("QA Rework",Pivot!$A$2:$B$30,2,FALSE),0) | F21: Do Not Call | G21: =IFERROR(VLOOKUP("Do Not Call",Pivot!$A$2:$B$30,2,FALSE),0) | H21: Cannot Afford Premium | I21: =IFERROR(VLOOKUP("Cannot Afford Premium",Pivot!$A$2:$B$30,2,FALSE),0)
B22: Selected | C22: =IFERROR(VLOOKUP("Selected",Pivot!$A$2:$B$30,2,FALSE),0) | F22: No Smartphones | G22: =IFERROR(VLOOKUP("No Smartphones",Pivot!$A$2:$B$30,2,FALSE),0) | H22: Not interested - Pitched | I22: =IFERROR(VLOOKUP("Not interested - Pitched",Pivot!$A$2:$B$30,2,FALSE),0)
B23: No Answer | C23: =IFERROR(VLOOKUP("No Answer",Pivot!$A$2:$B$30,2,FALSE),0) | F23: Client Deceased | G23: =IFERROR(VLOOKUP("Client Deceased",Pivot!$A$2:$B$30,2,FALSE),0) | H23: Affordability | I23: =IFERROR(VLOOKUP("Affordability",Pivot!$A$2:$B$30,2,FALSE),0)
B24: Busy Tone | C24: =IFERROR(VLOOKUP("Busy Tone",Pivot!$A$2:$B$30,2,FALSE),0) | F24: Right Party Not Available | G24: =IFERROR(VLOOKUP("Right Party Not Available",Pivot!$A$2:$B$30,2,FALSE),0) | H24: Quoted Client Not Interested | I24: =IFERROR(VLOOKUP("Quoted Client Not Interested",Pivot!$A$2:$B$30,2,FALSE),0)
B25: Dropped | C25: =IFERROR(VLOOKUP("Dropped",Pivot!$A$2:$B$30,2,FALSE),0) | F25: Client Overage Limit | G25: =IFERROR(VLOOKUP("Client Overage Limit",Pivot!$A$2:$B$30,2,FALSE),0) | H25: Not interested business does not use speed point mac | I25: =IFERROR(VLOOKUP("Not interested business does not use speed point mac",Pivot!$A$2:$B$30,2,FALSE),0)
B26: New | C26: =IFERROR(VLOOKUP("New",Pivot!$A$2:$B$30,2,FALSE),0) | F26: Language Barrier | G26: =IFERROR(VLOOKUP("Language Barrier",Pivot!$A$2:$B$30,2,FALSE),0) | H26: Call Back Technical Error | I26: =IFERROR(VLOOKUP("Call Back Technical Error",Pivot!$A$2:$B$30,2,FALSE),0)
B27: Call Dropped | C27: =IFERROR(VLOOKUP("Call Dropped",Pivot!$A$2:$B$30,2,FALSE),0) | F27: Non SA Citizen | G27: =IFERROR(VLOOKUP("Non SA Citizen",Pivot!$A$2:$B$30,2,FALSE),0) | H27: Not Interested Transaction Fees | I27: =IFERROR(VLOOKUP("Not Interested Transaction Fees",Pivot!$A$2:$B$30,2,FALSE),0)
B28: Inbound After Hours Drop | C28: =IFERROR(VLOOKUP("Inbound After Hours Drop",Pivot!$A$2:$B$30,2,FALSE),0) | F28: No Bank Account | G28: =IFERROR(VLOOKUP("No Bank Account",Pivot!$A$2:$B$30,2,FALSE),0) | H28: Cannot Afford | I28: =IFERROR(VLOOKUP("Cannot Afford",Pivot!$A$2:$B$30,2,FALSE),0)
B29: TPS Registered Number | C29: =IFERROR(VLOOKUP("TPS Registered Number",Pivot!$A$2:$B$30,2,FALSE),0) | F29: Client Underage | G29: =IFERROR(VLOOKUP("Client Underage",Pivot!$A$2:$B$30,2,FALSE),0) | H29: Not Interested Household Contents | I29: =IFERROR(VLOOKUP("Not Interested Household Contents",Pivot!$A$2:$B$30,2,FALSE),0)
B30: Temporary Disconnected Number | C30: =IFERROR(VLOOKUP("Temporary Disconnected Number",Pivot!$A$2:$B$30,2,FALSE),0) | F30: Go To The Branch | G30: =IFERROR(VLOOKUP("Go To The Branch",Pivot!$A$2:$B$30,2,FALSE),0) | H30: Call Back Hold | I30: =IFERROR(VLOOKUP("Call Back Hold",Pivot!$A$2:$B$30,2,FALSE),0)
B31: Bad Line Quality | C31: =IFERROR(VLOOKUP("Bad Line Quality",Pivot!$A$2:$B$30,2,FALSE),0) | F31: Completed | G31: =IFERROR(VLOOKUP("Completed",Pivot!$A$2:$B$30,2,FALSE),0) | H31: Declined Sale | I31: =IFERROR(VLOOKUP("Declined Sale",Pivot!$A$2:$B$30,2,FALSE),0)
B32: Inbound Abandon | C32: =IFERROR(VLOOKUP("Inbound Abandon",Pivot!$A$2:$B$30,2,FALSE),0) | F32: Cannot Afford Upfront Payment | G32: =IFERROR(VLOOKUP("Cannot Afford Upfront Payment",Pivot!$A$2:$B$30,2,FALSE),0)
B33: Outbound Pre-Routing Drop | C33: =IFERROR(VLOOKUP("Outbound Pre-Routing Drop",Pivot!$A$2:$B$30,2,FALSE),0) | F33: Account Suspended | G33: =IFERROR(VLOOKUP("Account Suspended",Pivot!$A$2:$B$30,2,FALSE),0)
B34: Engaged | C34: =IFERROR(VLOOKUP("Engaged",Pivot!$A$2:$B$30,2,FALSE),0) | F34: Insured at another company | G34: =IFERROR(VLOOKUP("Insured at another company",Pivot!$A$2:$B$30,2,FALSE),0)
B35: Disconnected | C35: =IFERROR(VLOOKUP("Disconnected",Pivot!$A$2:$B$30,2,FALSE),0) | F35: Scheduled Appointment | G35: =IFERROR(VLOOKUP("Scheduled Appointment",Pivot!$A$2:$B$30,2,FALSE),0)
B36: CONGESTED | C36: =IFERROR(VLOOKUP("CONGESTED",Pivot!$A$2:$B$30,2,FALSE),0) | F36: Refund Request | G36: =IFERROR(VLOOKUP("Refund Request",Pivot!$A$2:$B$30,2,FALSE),0)
B37: Flow Inbound Abandon | C37: =IFERROR(VLOOKUP("Flow Inbound Abandon",Pivot!$A$2:$B$30,2,FALSE),0) | F37: Does Not Qualify | G37: =IFERROR(VLOOKUP("Does Not Qualify",Pivot!$A$2:$B$30,2,FALSE),0)
B38: Multiple Calls | C38: =IFERROR(VLOOKUP("Multiple Calls",Pivot!$A$2:$B$30,2,FALSE),0) | F38: Does Not Have a Business | G38: =IFERROR(VLOOKUP("Does Not Have a Business",Pivot!$A$2:$B$30,2,FALSE),0)
B39: Missed | C39: =IFERROR(VLOOKUP("Missed",Pivot!$A$2:$B$30,2,FALSE),0) | F39: Refer To Store - Doesn't want to complete online | G39: =IFERROR(VLOOKUP("Refer To Store - Doesn't want to complete online",Pivot!$A$2:$B$30,2,FALSE),0)
B40: Answered | C40: =IFERROR(VLOOKUP("Answered",Pivot!$A$2:$B$30,2,FALSE),0) | F40: Does Not Need It Now | G40: =IFERROR(VLOOKUP("Does Not Need It Now",Pivot!$A$2:$B$30,2,FALSE),0)
B41: Customer drop | C41: =IFERROR(VLOOKUP("Customer drop",Pivot!$A$2:$B$30,2,FALSE),0) | F41: Technical Issue | G41: =IFERROR(VLOOKUP("Technical Issue",Pivot!$A$2:$B$30,2,FALSE),0)
B42: Auto Dial Disconnected | C42: =IFERROR(VLOOKUP("Auto Dial Disconnected",Pivot!$A$2:$B$30,2,FALSE),0) | F42: Unsuccessful Application | G42: =IFERROR(VLOOKUP("Unsuccessful Application",Pivot!$A$2:$B$30,2,FALSE),0)
B43: Disconnected Number Temporary | C43: =IFERROR(VLOOKUP("Disconnected Number Temporary",Pivot!$A$2:$B$30,2,FALSE),0)
A46: TOTAL LEADS DIALLED | B46: =SUM(C17:C43)+SUM(E17:E21)
...
